Workbook
Name AccumulatorStatuses: INDIRECT({"Accumulator!$I$8","Accumulator!$P$8","Accumulator!$V$8","Accumulator!$AC$8","Accumulator!$Z$52","Accumulator!$Q$52","Accumulator!$H$52","Accumulator!$F$58"})
Name BattCellCapacity: Datasheets!$D$5
Name BattCellMaxContI: Datasheets!$D$10
Name BattCellMaxI: Datasheets!$D$9
Name BattCellMaxV: Datasheets!$D$6
Name BattCellNomV: Datasheets!$D$7
Name BusCap: PrechargeDischarge!$D$10
Name CellsPerTempSensor: 'Tractive Battery'!$Q$27
Name ConductorNames: Datasheets!$A$20:$A$38
Name ConductorsTable: Datasheets!$A$20:$I$38
Name ConnectorNames: Datasheets!$A$74:$A$92
Name ConnectorsTable: Datasheets!$A$74:$F$92
Name ContactorNames: Datasheets!$A$66:$A$70
Name ContactorsTable: Datasheets!$A$66:$I$70
Name DischargeRes: PrechargeDischarge!$J$6
Name ErrorText: "WARNING"
Name FuseNames: Datasheets!$A$42:$A$53
Name FusesTable: Datasheets!$A$42:$G$53
Name FusibleLink_Current1: 'Tractive Battery'!#REF!
Name FusibleLink_Current10: 'Tractive Battery'!#REF!
Name FusibleLink_Current11: 'Tractive Battery'!#REF!
Name FusibleLink_Current12: 'Tractive Battery'!#REF!
Name FusibleLink_Current13: 'Tractive Battery'!#REF!
Name FusibleLink_Current14: 'Tractive Battery'!#REF!
Name FusibleLink_Current15: 'Tractive Battery'!#REF!
Name FusibleLink_Current16: 'Tractive Battery'!#REF!
Name FusibleLink_Current2: 'Tractive Battery'!#REF!
Name FusibleLink_Current3: 'Tractive Battery'!#REF!
Name FusibleLink_Current4: 'Tractive Battery'!#REF!
Name FusibleLink_Current5: 'Tractive Battery'!#REF!
Name FusibleLink_Current6: 'Tractive Battery'!#REF!
Name FusibleLink_Current7: 'Tractive Battery'!#REF!
Name FusibleLink_Current8: 'Tractive Battery'!#REF!
Name FusibleLink_Current9: 'Tractive Battery'!#REF!
Name FusibleLink_Time1: 'Tractive Battery'!#REF!
Name FusibleLink_Time10: 'Tractive Battery'!#REF!
Name FusibleLink_Time11: 'Tractive Battery'!#REF!
Name FusibleLink_Time12: 'Tractive Battery'!#REF!
Name FusibleLink_Time13: 'Tractive Battery'!#REF!
Name FusibleLink_Time14: 'Tractive Battery'!#REF!
Name FusibleLink_Time15: 'Tractive Battery'!#REF!
Name FusibleLink_Time16: 'Tractive Battery'!#REF!
Name FusibleLink_Time2: 'Tractive Battery'!#REF!
Name FusibleLink_Time3: 'Tractive Battery'!#REF!
Name FusibleLink_Time4: 'Tractive Battery'!#REF!
Name FusibleLink_Time5: 'Tractive Battery'!#REF!
Name FusibleLink_Time6: 'Tractive Battery'!#REF!
Name FusibleLink_Time7: 'Tractive Battery'!#REF!
Name FusibleLink_Time8: 'Tractive Battery'!#REF!
Name FusibleLink_Time9: 'Tractive Battery'!#REF!
Name IncompleteText: "BLANK"
Name InsulationNames: Datasheets!$A$96:$A$105
Name InsulationsTable: Datasheets!$A$96:$H$105
Name MainFuseA: 'Tractive Battery'!$W$20
Name MaxTSVoltage: 'Tractive Battery'!$G$4
Name NominalTSVoltage: 'Tractive Battery'!$G$5
Name NumAccum: 'Tractive Battery'!$G$3
Name OKText: "OK"
Name PrechargeRes: PrechargeDischarge!$D$6
Name ResistorsNames: Datasheets!$A$57:$A$62

Sheet Overview
A1: Instructions | J1: Status
A2: Complete and submit the ESF using Microsoft Excel only. Google Sheets and other spreadsheet programs may alter formatting or protection and will result in automatic rejection. Input Cells: Cells requiring user input have an orange background. Status Indicators: Cells, sections, and worksheets have an overall status, indicated by blue background cells. Images and Schematics: Paste images or schematics over the specified area. Use high-resolution images and resize them appropriately. Datasheets: Provide a hyperlink to the manufacturer's datasheet where requested. For long datasheets, provide a a page number reference. Additional Comments: Use "Additional Comments" sections for information not covered by the specified fields. These sections are optional. | J2: Datasheets | L2: =Datasheets!C1 -> BLANK
J3: TS Schematics | L3: ='TS Schematics'!B1 -> BLANK
J4: Tractive Battery | L4: ='Tractive Battery'!B1 -> BLANK
J5: Precharge/Discharge | L5: =PrechargeDischarge!B1 -> BLANK
J6: Charging | L6: =Charging!B1 -> BLANK
J7: Shutdown Circuit | L7: ='Shutdown Circuit'!B1 -> BLANK
J8: Torque Security | L8: ='Torque Security'!$B$1 -> BLANK
J9: Other | L9: =Other!B1 -> BLANK
J11: Team Name
J12: University
J13: Competition Year | L13: 2027
J15: Max TS Voltage | L15: =MaxTSVoltage -> 0 | M15: V
J16: Main Fuse | L16: =MainFuseA -> #N/A | M16: A
A19: Additional Comments
A38: Template Revision History
A39: Version | B39: Date | C39: Comment
A40: 2.7 | B40: 45929 | C40: Updated for 2027 rules and terminology, general bug fixes.
A41: 2.6 | B41: 45921 | C41: Updated for 2026 rules/terminology; general fixes; added dropdown for insulator flammability rating; added check for precharge/discharge relay switching power; added rule T.4.2.3 compliance check; added cell vs. cell fuse rating check; added clarification popups
A46: 2.4 | B46: 45565 | C46: Updated for 2025 rules and terminology, general bug fixes.
A47: 2.3 | B47: 45228 | C47: Updated for 2024 season.
A48: 2.2 | B48: 44868 | C48: Updated for 2023 season.
A49: 2.1 | B49: 44491 | C49: Updated for 2022 season.
A50: 2.0 | B50: 44162 | C50: Multiple updates and bug fixes.

Sheet Datasheets
B1: Status | C1: {=IF( SUM(COUNTIF(INDIRECT({"Datasheets!$F$2","Datasheets!$K$17","Datasheets!$K$39","Datasheets!$N$54","Datasheets!$K$63","Datasheets!$J$71","Datasheets!$L$93"}), "="&IncompleteText))>0, IncompleteText, IF(SUM(COUNTIF(INDIRECT({"Datasheets!$F$2","Datasheets!$K$17","Datasheets!$K$39","Datasheets!$N$54","Datasheets!$K$63","Datasheets!$J$71","Datasheets!$L$93"}), "="&ErrorText)), ErrorText, OKText))} -> BLANK
B2: Battery Cell | F2: =IF(COUNTBLANK(D3:D15)>0, IncompleteText, OKText) -> BLANK
B3: Make
B4: Model
B5: Nominal Capacity | E5: Ahr
B6: Maximum Voltage | E6: V
B7: Nominal Voltage | E7: V
B8: Minimum Voltage | E8: V
B9: Max output current | E9: A
B10: Max continuous current | E10: A
B11: Max regen current | E11: A
B12: Max Cell temp | E12: C
B13: Cell Chemistry
B14: Datasheet
B15: SDS
B16: Additional Comments
B18: Conductors | K18: =IF(COUNTIF(K20:K38, "="&IncompleteText), IncompleteText, IF(COUNTIF(K20:K38, "="&ErrorText), ErrorText, OKText)) -> BLANK
B19: Manufacturer | C19: Part Number | D19: Size [mm2] | E19: Voltage [V] | F19: Ampacity [A] | G19: Max Temp [C] | H19: Datasheet | J19: Location Used | L19: Additional Comments | Q19: Rules References
A20: =CONCATENATE(INDIRECT(CONCATENATE("B",ROW(A20))), " ", INDIRECT(CONCATENATE("C",ROW(A20)))) | K20: =IF(COUNTBLANK(B20:J20)=9,IncompleteText,IF(AND(COUNTBLANK(B20:J20)=1, G20>=90),OKText,ErrorText)) -> BLANK | Q20: EV.5.2.1 EV.5.2.5 EV.7.3 EV.7.3.2 EV.7.6.4
A21: =CONCATENATE(INDIRECT(CONCATENATE("B",ROW(A21))), " ", INDIRECT(CONCATENATE("C",ROW(A21)))) | K21: =IF(COUNTBLANK(B21:J21)=9,"",IF(AND(COUNTBLANK(B21:J21)=1, G21>=90),OKText,ErrorText))
A22: =CONCATENATE(INDIRECT(CONCATENATE("B",ROW(A22))), " ", INDIRECT(CONCATENATE("C",ROW(A22)))) | K22: =IF(COUNTBLANK(B22:J22)=9,"",IF(AND(COUNTBLANK(B22:J22)=1, G22>=90),OKText,ErrorText))
A23: =CONCATENATE(INDIRECT(CONCATENATE("B",ROW(A23))), " ", INDIRECT(CONCATENATE("C",ROW(A23)))) | K23: =IF(COUNTBLANK(B23:J23)=9,"",IF(AND(COUNTBLANK(B23:J23)=1, G23>=90),OKText,ErrorText))
A24: =CONCATENATE(INDIRECT(CONCATENATE("B",ROW(A24))), " ", INDIRECT(CONCATENATE("C",ROW(A24)))) | K24: =IF(COUNTBLANK(B24:J24)=9,"",IF(AND(COUNTBLANK(B24:J24)=1, G24>=90),OKText,ErrorText))
A25: =CONCATENATE(INDIRECT(CONCATENATE("B",ROW(A25))), " ", INDIRECT(CONCATENATE("C",ROW(A25)))) | K25: =IF(COUNTBLANK(B25:J25)=9,"",IF(AND(COUNTBLANK(B25:J25)=1, G25>=90),OKText,ErrorText))
A26: =CONCATENATE(INDIRECT(CONCATENATE("B",ROW(A26))), " ", INDIRECT(CONCATENATE("C",ROW(A26)))) | K26: =IF(COUNTBLANK(B26:J26)=9,"",IF(AND(COUNTBLANK(B26:J26)=1, G26>=90),OKText,ErrorText))
A27: =CONCATENATE(INDIRECT(CONCATENATE("B",ROW(A27))), " ", INDIRECT(CONCATENATE("C",ROW(A27)))) | K27: =IF(COUNTBLANK(B27:J27)=9,"",IF(AND(COUNTBLANK(B27:J27)=1, G27>=90),OKText,ErrorText))
A28: =CONCATENATE(INDIRECT(CONCATENATE("B",ROW(A28))), " ", INDIRECT(CONCATENATE("C",ROW(A28)))) | K28: =IF(COUNTBLANK(B28:J28)=9,"",IF(AND(COUNTBLANK(B28:J28)=1, G28>=90),OKText,ErrorText))
A29: =CONCATENATE(INDIRECT(CONCATENATE("B",ROW(A29))), " ", INDIRECT(CONCATENATE("C",ROW(A29)))) | K29: =IF(COUNTBLANK(B29:J29)=9,"",IF(AND(COUNTBLANK(B29:J29)=1, G29>=90),OKText,ErrorText))
A30: =CONCATENATE(INDIRECT(CONCATENATE("B",ROW(A30))), " ", INDIRECT(CONCATENATE("C",ROW(A30)))) | K30: =IF(COUNTBLANK(B30:J30)=9,"",IF(AND(COUNTBLANK(B30:J30)=1, G30>=90),OKText,ErrorText))
A31: =CONCATENATE(INDIRECT(CONCATENATE("B",ROW(A31))), " ", INDIRECT(CONCATENATE("C",ROW(A31)))) | K31: =IF(COUNTBLANK(B31:J31)=9,"",IF(AND(COUNTBLANK(B31:J31)=1, G31>=90),OKText,ErrorText))
A32: =CONCATENATE(INDIRECT(CONCATENATE("B",ROW(A32))), " ", INDIRECT(CONCATENATE("C",ROW(A32)))) | K32: =IF(COUNTBLANK(B32:J32)=9,"",IF(AND(COUNTBLANK(B32:J32)=1, G32>=90),OKText,ErrorText))
... A38: =CONCATENATE(INDIRECT(CONCATENATE("B",ROW(A38))), " ", INDIRECT(CONCATENATE("C",ROW(A38)))) | K38: =IF(COUNTBLANK(B38:J38)=9,"",IF(AND(COUNTBLANK(B38:J38)=1, G38>=90),OKText,ErrorText))
A39: =CONCATENATE(INDIRECT(CONCATENATE("B",ROW(A39))), " ", INDIRECT(CONCATENATE("C",ROW(A39))))
A40: =CONCATENATE(INDIRECT(CONCATENATE("B",ROW(A40))), " ", INDIRECT(CONCATENATE("C",ROW(A40)))) -> Fuses | B40: Fuses | K40: =IF(COUNTIF(K42:K53, "="&IncompleteText), IncompleteText, IF(COUNTIF(K42:K53, "="&ErrorText), ErrorText, OKText)) -> BLANK
A41: =CONCATENATE(INDIRECT(CONCATENATE("B",ROW(A41))), " ", INDIRECT(CONCATENATE("C",ROW(A41)))) -> Manufacturer Part Number | B41: Manufacturer | C41: Part Number | D41: Voltage [V] | E41: AC/DC | F41: Current [A] | G41: Interrupt [A] | H41: Datasheet | J41: Location Used | L41: Additional Comments | Q41: Rules References
A42: =CONCATENATE(INDIRECT(CONCATENATE("B",ROW(A42))), " ", INDIRECT(CONCATENATE("C",ROW(A42)))) | K42: =IF(COUNTBLANK(B42:J42)=9,IncompleteText,IF(COUNTBLANK(B42:J42)=1,OKText,ErrorText)) -> BLANK | Q42: EV.5.2.1 EV.7.6
A43: =CONCATENATE(INDIRECT(CONCATENATE("B",ROW(A43))), " ", INDIRECT(CONCATENATE("C",ROW(A43)))) | K43: =IF(COUNTBLANK(B43:J43)=9,"",IF(COUNTBLANK(B43:J43)=1,OKText,ErrorText))
A44: =CONCATENATE(INDIRECT(CONCATENATE("B",ROW(A44))), " ", INDIRECT(CONCATENATE("C",ROW(A44)))) | K44: =IF(COUNTBLANK(B44:J44)=9,"",IF(COUNTBLANK(B44:J44)=1,OKText,ErrorText))
A45: =CONCATENATE(INDIRECT(CONCATENATE("B",ROW(A45))), " ", INDIRECT(CONCATENATE("C",ROW(A45)))) | K45: =IF(COUNTBLANK(B45:J45)=9,"",IF(COUNTBLANK(B45:J45)=1,OKText,ErrorText))
A46: =CONCATENATE(INDIRECT(CONCATENATE("B",ROW(A46))), " ", INDIRECT(CONCATENATE("C",ROW(A46)))) | K46: =IF(COUNTBLANK(B46:J46)=9,"",IF(COUNTBLANK(B46:J46)=1,OKText,ErrorText))
...

Sheet TS Schematics
A1: Status | B1: {=IF(SUM(COUNTIF(INDIRECT({"'TS Schematics'!$K$28","'TS Schematics'!$W$28","'TS Schematics'!$K$46"}), "="&IncompleteText)), IncompleteText, IF(SUM(COUNTIF(INDIRECT({"'TS Schematics'!$K$28","'TS Schematics'!$W$28","'TS Schematics'!$K$46"}), "="&ErrorText)), ErrorText, OKText))} -> BLANK
A2: Tractive System Schematic | M2: Tractive Battery TS Schematic | Y2: Additional Comments
A28: Vehicle Tractive System Schematic Shows | K28: =IF(COUNTIF(K30:K43, "="&IncompleteText), IncompleteText, IF(COUNTIF(K30:K43, "="&ErrorText), ErrorText, OKText)) -> BLANK | M28: Tractive Battery TS Schematic Shows | W28: =IF(COUNTIF(W30:W41, "="&IncompleteText), IncompleteText, IF(COUNTIF(W30:W41, "="&ErrorText), ErrorText, OKText)) -> BLANK
A29: Rules References | M29: Rules References
C30: Shows details of all TS circuits outside of tractive battery | K30: =IF(ISBLANK(J30),IncompleteText, IF(J30, OKText, ErrorText)) -> BLANK | O30: Details of all TS circuits within tractive battery | W30: =IF(ISBLANK(V30),IncompleteText, IF(V30, OKText, ErrorText)) -> BLANK
C31: Tractive battery is shown as a single element (without internal details) | K31: =IF(ISBLANK(J31),IncompleteText, IF(J31, OKText, ErrorText)) -> BLANK | O31: All wire gauges labeled | W31: =IF(ISBLANK(V31),IncompleteText, IF(V31, OKText, ErrorText)) -> BLANK
C32: All wire gauges labeled | K32: =IF(ISBLANK(J32),IncompleteText, IF(J32, OKText, ErrorText)) -> BLANK | O32: All fuses labeled with ampacity | W32: =IF(ISBLANK(V32),IncompleteText, IF(V32, OKText, ErrorText)) -> BLANK
C33: All fuses labeled with ampacity | K33: =IF(ISBLANK(J33),IncompleteText, IF(J33, OKText, ErrorText)) -> BLANK | M33: EV.7.6.6 | O33: All wires > 150mm have a fuse within the first 150mm from the source | W33: =IF(ISBLANK(V33),IncompleteText, IF(V33, OKText, ErrorText)) -> BLANK
A34: EV.7.6.6 | C34: All wires > 150mm have a fuse within the first 150mm from the source | K34: =IF(ISBLANK(J34),IncompleteText, IF(J34, OKText, ErrorText)) -> BLANK | O34: Fuse locations represent physical location | W34: =IF(ISBLANK(V34),IncompleteText, IF(V34, OKText, ErrorText)) -> BLANK
C35: Fuse locations represent physical location | K35: =IF(ISBLANK(J35),IncompleteText, IF(J35, OKText, ErrorText)) -> BLANK | O35: Connectors labeled with Make/Model | W35: =IF(ISBLANK(V35),IncompleteText, IF(V35, OKText, ErrorText)) -> BLANK
C36: Enclosures shown | K36: =IF(ISBLANK(J36),IncompleteText, IF(J36, OKText, ErrorText)) -> BLANK | O36: Standard schematic symbols used | W36: =IF(ISBLANK(V36),IncompleteText, IF(V36, OKText, ErrorText)) -> BLANK
C37: Connectors labeled with Make/Model | K37: =IF(ISBLANK(J37),IncompleteText, IF(J37, OKText, ErrorText)) -> BLANK | O37: All text is readable (zooming is allowed) | W37: =IF(ISBLANK(V37),IncompleteText, IF(V37, OKText, ErrorText)) -> BLANK
C38: Standard schematic symbols used | K38: =IF(ISBLANK(J38),IncompleteText, IF(J38, OKText, ErrorText)) -> BLANK | M38: EV.5.4 | O38: IRs | W38: =IF(ISBLANK(V38),IncompleteText, IF(V38, OKText, ErrorText)) -> BLANK
C39: All text is readable (zooming is allowed) | K39: =IF(ISBLANK(J39),IncompleteText, IF(J39, OKText, ErrorText)) -> BLANK | M39: EV.5.3 | O39: Maintenance plugs | W39: =IF(ISBLANK(V39),IncompleteText, IF(V39, OKText, ErrorText)) -> BLANK
A40: EV.5.8 | C40: TSMPs | K40: =IF(ISBLANK(J40),IncompleteText, IF(J40, OKText, ErrorText)) -> BLANK | O40: Cells (details of all intercell connections may be abstracted) | W40: =IF(ISBLANK(V40),IncompleteText, IF(V40, OKText, ErrorText)) -> BLANK
C41: Motor Controller | K41: =IF(ISBLANK(J41),IncompleteText, IF(J41, OKText, ErrorText)) -> BLANK | M41: EV.5.7 | O41: Voltage Indicator (must be powered directly by TS) | W41: =IF(ISBLANK(V41),IncompleteText, IF(V41, OKText, ErrorText)) -> BLANK
C42: Motor | K42: =IF(ISBLANK(J42),IncompleteText, IF(J42, OKText, ErrorText)) -> BLANK
A43: EV.5.8.5 | C43: TSMPs not fused | K43: =IF(ISBLANK(J43),IncompleteText, IF(J43, OKText, ErrorText)) -> BLANK
A46: Must be shown on at least one schematic | K46: =IF(COUNTIF(K48:K55, "="&IncompleteText), IncompleteText, IF(COUNTIF(K48:K55, "="&ErrorText), ErrorText, OKText)) -> BLANK
A47: Rules References
A48: EV.8.6 | C48: IMD | K48: =IF(ISBLANK(J48),IncompleteText, IF(J48, OKText, ErrorText)) -> BLANK
A49: EV.5.5 | C49: MSD | K49: =IF(ISBLANK(J49),IncompleteText, IF(J49, OKText, ErrorText)) -> BLANK
A50: EV.5.6 | C50: Precharge | K50: =IF(ISBLANK(J50),IncompleteText, IF(J50, OKText, ErrorText)) -> BLANK
A51: EV.5.6 | C51: Discharge | K51: =IF(ISBLANK(J51),IncompleteText, IF(J51, OKText, ErrorText)) -> BLANK
A52: EV.3.2; EV.5.1.2 | C52: Energy Meter (shunt and TS sense connection) | K52: =IF(ISBLANK(J52),IncompleteText, IF(J52, OKText, ErrorText)) -> BLANK
A53: EV.5.6.3.b | C53: Discharge still functions when MSD is opened | K53: =IF(ISBLANK(J53),IncompleteText, IF(J53, OKText, ErrorText)) -> BLANK
A54: EV.5.6.3.c | C54: Discharge is not fused | K54: =IF(ISBLANK(J54),IncompleteText, IF(J54, OKText, ErrorText)) -> BLANK
A55: EV.5.4.3.b | C55: Complete galvanic isolation when IRs are open | K55: =IF(ISBLANK(J55),IncompleteText, IF(J55, OKText, ErrorText)) -> BLANK

Sheet Tractive Battery
A1: Status | B1: =IF( OR( 'Tractive Battery'!$I$4=IncompleteText, 'Tractive Battery'!$L$8=IncompleteText, 'Tractive Battery'!$S$8=IncompleteText, 'Tractive Battery'!$Y$8=IncompleteText, 'Tractive Battery'!$AF$8=IncompleteText, 'Tractive Battery'!$AB$53=IncompleteText, 'Tractive Battery'!$S$53=IncompleteText, 'Tractive Battery'!$J$53=IncompleteText, 'Tractive Battery'!$H$63=IncompleteText, 'Tractive Battery'!$AK$53=IncompleteText, 'Tractive Battery'!$AT$53=IncompleteText, 'Tractive Battery'!$BC$53=IncompleteText ), IncompleteText, IF( OR( 'Tractive Battery'!$I$4=ErrorText, 'Tractive Battery'!$L$8=ErrorText, 'Tractive Battery'!$S$8=ErrorText, 'Tractive Battery'!$Y$8=ErrorText, 'Tractive Battery'!$AF$8=ErrorText, 'Tractive Battery'!$AB$53=ErrorText, 'Tractive Battery'!$S$53=ErrorText, 'Tractive Battery'!$J$53=ErrorText, 'Tractive Battery'!$H$63=ErrorText, 'Tractive Battery'!$AK$53=ErrorText, 'Tractive Battery'!$AT$53=ErrorText, 'Tractive Battery'!$BC$53=ErrorText ), ErrorText, OKText ) ) -> BLANK
A4: Maximum TS Voltage | G4: =SUM(C12:C29)*BattCellMaxV -> 0 | H4: V | I4: =IF(G4 > 600, ErrorText, OKText) -> OK
A5: Nominal TS Voltage | G5: =SUM(C12:C29)*BattCellNomV -> 0 | H5: V
A6: Total Cells | G6: =SUMPRODUCT(B12:B29,C12:C29) -> 0
A8: Module Data | L8: =IF(COUNTIF(L9:L29, "="&IncompleteText), IncompleteText, IF(COUNTIF(L9:L29, "="&ErrorText), ErrorText, OKText)) -> BLANK | M8: BMS | S8: =IF(COUNTIF(S9:S32, "="&IncompleteText), IncompleteText, IF(COUNTIF(S9:S32, "="&ErrorText), ErrorText, OKText)) -> BLANK | T8: Maintenance Plugs | Y8: =IF(COUNTIF(Y9:Y28, "="&IncompleteText), IncompleteText, IF(COUNTIF(Y9:Y28, "="&ErrorText), ErrorText, OKText)) -> BLANK | Z8: Insulating Materials | AF8: =IF(COUNTIF(AF9:AF20, "="&IncompleteText), IncompleteText, IF(COUNTIF(AF9:AF20, "="&ErrorText), ErrorText, OKText)) -> BLANK | AG8: Additional Comments
A9: Cell Connection Order | L9: =IF(ISBLANK(F9), IncompleteText, OKText) -> BLANK | T9: Connector | Y9: =IF(ISBLANK(W9), IncompleteText, OKText) -> BLANK | Z9: Between cells and accum. container | AF9: =IF(ISBLANK(AD9), IncompleteText, OKText) -> BLANK
A10: Module | B10: Parallel cells | C10: Series cells | F10: Temp Sensors | G10: Tractive Battery Number | H10: Max Voltage [V] | J10: Module Energy [MJ] | M10: BMS Source | S10: =IF(ISBLANK(Q10), IncompleteText, OKText) -> BLANK | T10: Ampacity | W10: =VLOOKUP(W9, ConnectorsTable, 5, FALSE) -> #N/A | X10: A | Y10: =IF(ISERROR(W10),IncompleteText,IF(W10>=MainFuseA,OKText,ErrorText)) -> BLANK | Z10: Voltage Rating | AD10: =VLOOKUP(AD9, InsulationsTable, 6, FALSE) -> #N/A | AE10: V | AF10: =IF(ISERROR(AD10), IncompleteText, IF(AD10 < MaxTSVoltage, ErrorText, OKText)) -> BLANK
M11: Make | P11: Model | S11: =IF(Q10="Purchased", IF(OR(ISBLANK(N11), ISBLANK(Q11)), IncompleteText, OKText), "") | Z11: Temperature Rating | AD11: =VLOOKUP(AD9, InsulationsTable, 7, FALSE) -> #N/A | AE11: C | AF11: =IF(ISERROR(AD11), IncompleteText, IF(AD11 < 90, ErrorText, OKText)) -> BLANK
A12: 1 | H12: =C12*BattCellMaxV -> 0 | J12: =H12*B12*BattCellCapacity*0.0036 -> 0 | L12: =IF(COUNTBLANK(B12:C12)+COUNTBLANK(F12:G12) > 0, IncompleteText, IF(OR(H12>120, J12>6), ErrorText, OKText)) -> BLANK | M12: Galvanic Isolation TS to GLV | R12: V | S12: =IF(ISBLANK(Q12), IncompleteText, IF(Q12<G4, ErrorText, OKText)) -> BLANK | Z12: Flammability Rating | AD12: =VLOOKUP(AD9, InsulationsTable, 8, FALSE) -> #N/A | AF12: =IF(ISERROR(AD12), IncompleteText, IF(ISNUMBER(MATCH(AD12,{"UL94 V-0","UL94 5VA","UL94 5VB","UL94 VTM-0","FAR 25.853"},0)), OKText, ErrorText)) -> BLANK
A13: 2 | H13: =C13*BattCellMaxV -> 0 | J13: =H13*B13*BattCellCapacity*0.0036 -> 0 | L13: =IF(COUNTBLANK(B13:C13)+COUNTBLANK(F13:G13)=4,"",IF(COUNTBLANK(B13:C13)+COUNTBLANK(F13:G13) > 0, IncompleteText, IF(OR(H13>120, J13>6), ErrorText, OKText))) | M13: Galvanic Isolation between modules | R13: V | S13: =IF(ISBLANK(Q13), IncompleteText, IF(Q13<MAX(H12:I29), ErrorText, OKText)) -> BLANK | T13: IR | Z13: On top of cells | AF13: =IF(ISBLANK(AD13), IncompleteText, OKText) -> BLANK
A14: 3 | H14: =C14*BattCellMaxV -> 0 | J14: =H14*B14*BattCellCapacity*0.0036 -> 0 | L14: =IF(COUNTBLANK(B14:C14)+COUNTBLANK(F14:G14)=4,"",IF(COUNTBLANK(B14:C14)+COUNTBLANK(F14:G14) > 0, IncompleteText, IF(OR(H14>120, J14>6), ErrorText, OKText))) | M14: Galvanic Isolation device | S14: =IF($Q$10="Team Built", IF(ISBLANK(Q14), IncompleteText, OKText), "") | T14: Make/Model | Y14: =IF(ISBLANK(W14), IncompleteText, OKText) -> BLANK | Z14: Voltage Rating | AD14: =VLOOKUP(AD13, InsulationsTable, 6, FALSE) -> #N/A | AE14: V | AF14: =IF(ISERROR(AD14), IncompleteText, IF(AD14 < MaxTSVoltage, ErrorText, OKText)) -> BLANK
A15: 4 | H15: =C15*BattCellMaxV -> 0 | J15: =H15*B15*BattCellCapacity*0.0036 -> 0 | L15: =IF(COUNTBLANK(B15:C15)+COUNTBLANK(F15:G15)=4,"",IF(COUNTBLANK(B15:C15)+COUNTBLANK(F15:G15) > 0, IncompleteText, IF(OR(H15>120, J15>6), ErrorText, OKText))) | M15: Gavlanic Isolation device datasheet | S15: =IF($Q$10="Team Built", IF(ISBLANK(Q15), IncompleteText, OKText), "") | T15: Contact Voltage Rating | W15: =VLOOKUP(W14, ContactorsTable, 4, FALSE) -> #N/A | X15: V | Y15: =IF(ISERROR(W15), IncompleteText, IF(W15 < MaxTSVoltage, ErrorText, OKText)) -> BLANK | Z15: Temperature Rating | AD15: =VLOOKUP(AD13, InsulationsTable, 7, FALSE) -> #N/A | AE15: C | AF15: =IF(ISERROR(AD15), IncompleteText, IF(AD15 < 90, ErrorText, OKText)) -> BLANK
A16: 5 | H16: =C16*BattCellMaxV -> 0 | J16: =H16*B16*BattCellCapacity*0.0036 -> 0 | L16: =IF(COUNTBLANK(B16:C16)+COUNTBLANK(F16:G16)=4,"",IF(COUNTBLANK(B16:C16)+COUNTBLANK(F16:G16) > 0, IncompleteText, IF(OR(H16>120, J16>6), ErrorText, OKText))) | M16: Voltage Sense Leads | T16: Max switching current | W16: =VLOOKUP(W14, ContactorsTable, 6, FALSE) -> #N/A | X16: A | Z16: Flammability Rating | AD16: =VLOOKUP(AD13, InsulationsTable, 8, FALSE) -> #N/A | AF16: =IF(ISERROR(AD16), IncompleteText, IF(ISNUMBER(MATCH(AD16,{"UL94 V-0","UL94 5VA","UL94 5VB","UL94 VTM-0","FAR 25.853"},0)), OKText, ErrorText)) -> BLANK
A17: 6 | H17: =C17*BattCellMaxV -> 0 | J17: =H17*B17*BattCellCapacity*0.0036 -> 0 | L17: =IF(COUNTBLANK(B17:C17)+COUNTBLANK(F17:G17)=4,"",IF(COUNTBLANK(B17:C17)+COUNTBLANK(F17:G17) > 0, IncompleteText, IF(OR(H17>120, J17>6), ErrorText, OKText))) | M17: Maximum Unfused Lead Length | R17: mm | S17: =IF(ISBLANK(Q17), IncompleteText, IF(Q17>150, ErrorText, OKText)) -> BLANK | T17: Max continuous current | W17: =VLOOKUP(W14, ContactorsTable, 5, FALSE) -> #N/A | X17: A | Y17: =IF(ISERROR(W17), IncompleteText, IF(W17>=MainFuseA, OKText, ErrorText)) -> BLANK | Z17: Separating IRs and Fuse from cells | AF17: =IF(ISBLANK(AD17), IncompleteText, OKText) -> BLANK
A18: 7 | H18: =C18*BattCellMaxV -> 0 | J18: =H18*B18*BattCellCapacity*0.0036 -> 0 | L18: =IF(COUNTBLANK(B18:C18)+COUNTBLANK(F18:G18)=4,"",IF(COUNTBLANK(B18:C18)+COUNTBLANK(F18:G18) > 0, IncompleteText, IF(OR(H18>120, J18>6), ErrorText, OKText))) | M18: Sense Lead Overcurrent Protection Device | S18: =IF(ISBLANK(Q18), IncompleteText, OKText) -> BLANK | T18: Main Fuse | Z18: Voltage Rating | AD18: =VLOOKUP(AD17, InsulationsTable, 6, FALSE) -> #N/A | AE18: V | AF18: =IF(ISERROR(AD18), IncompleteText, IF(AD18 < MaxTSVoltage, ErrorText, OKText)) -> BLANK
A19: 8 | H19: =C19*BattCellMaxV -> 0 | J19: =H19*B19*BattCellCapacity*0.0036 -> 0 | L19: =IF(COUNTBLANK(B19:C19)+COUNTBLANK(F19:G19)=4,"",IF(COUNTBLANK(B19:C19)+COUNTBLANK(F19:G19) > 0, IncompleteText, IF(OR(H19>120, J19>6), ErrorText, OKText))) | M19: Overcurrent Location | S19: =IF(ISBLANK(Q19), IncompleteText, OKText) -> BLANK | T19: Main Fuse | Y19: =IF(ISBLANK(W19), IncompleteText, OKText) -> BLANK | Z19: Temperature Rating | AD19: =VLOOKUP(AD17, InsulationsTable, 7, FALSE) -> #N/A | AE19: C | AF19: =IF(ISERROR(AD19), IncompleteText, IF(AD19 < 90, ErrorText, OKText)) -> BLANK
A20: 9 | H20: =C20*BattCellMaxV -> 0 | J20: =H20*B20*BattCellCapacity*0.0036 -> 0 | L20: =IF(COUNTBLANK(B20:C20)+COUNTBLANK(F20:G20)=4,"",IF(COUNTBLANK(B20:C20)+COUNTBLANK(F20:G20) > 0, IncompleteText, IF(OR(H20>120, J20>6), ErrorText, OKText))) | M20: Overcurrent Other Location | S20: =IF(Q19="Other", IF(ISBLANK(Q20), IncompleteText, OKText), "") | T20: Main fuse ampacity | W20: =VLOOKUP(W19, FusesTable, 6, FALSE) -> #N/A | X20: A | Z20: Flammability Rating | AD20: =VLOOKUP(AD17, InsulationsTable, 8, FALSE) -> #N/A | AF20: =IF(ISERROR(AD20), IncompleteText, IF(ISNUMBER(MATCH(AD20,{"UL94 V-0","UL94 5VA","UL94 5VB","UL94 VTM-0","FAR 25.853"},0)), OKText, ErrorText)) -> BLANK
A21: 10 | H21: =C21*BattCellMaxV -> 0 | J21: =H21*B21*BattCellCapacity*0.0036 -> 0 | L21: =IF(COUNTBLANK(B21:C21)+COUNTBLANK(F21:G21)=4,"",IF(COUNTBLANK(B21:C21)+COUNTBLANK(F21:G21) > 0, IncompleteText, IF(OR(H21>120, J21>6), ErrorText, OKText))) | M21: Overcurrent Voltage Rating | Q21: =VLOOKUP(Q18, FusesTable, 4, FALSE) -> #N/A | R21: V | S21: =IF(ISERROR(Q21), IncompleteText, IF(Q21 < MAX(H12:I29), ErrorText, OKText)) -> BLANK | T21: Main fuse voltage | W21: =VLOOKUP(W19, FusesTable, 4, FALSE) -> #N/A | X21: V | Y21: =IF(ISERROR(W21), IncompleteText,IF(W21 < MaxTSVoltage, ErrorText, OKText)) -> BLANK
A22: 11 | H22: =C22*BattCellMaxV -> 0 | J22: =H22*B22*BattCellCapacity*0.0036 -> 0 | L22: =IF(COUNTBLANK(B22:C22)+COUNTBLANK(F22:G22)=4,"",IF(COUNTBLANK(B22:C22)+COUNTBLANK(F22:G22) > 0, IncompleteText, IF(OR(H22>120, J22>6), ErrorText, OKText))) | M22: Overcurrent Current Rating | Q22: =VLOOKUP(Q18, FusesTable, 6, FALSE) -> #N/A | R22: A | T22: MSD
A23: 12 | H23: =C23*BattCellMaxV -> 0 | J23: =H23*B23*BattCellCapacity*0.0036 -> 0 | L23: =IF(COUNTBLANK(B23:C23)+COUNTBLANK(F23:G23)=4,"",IF(COUNTBLANK(B23:C23)+COUNTBLANK(F23:G23) > 0, IncompleteText, IF(OR(H23>120, J23>6), ErrorText, OKText))) | M23: Overcurrent Interrupt Rating | Q23: =VLOOKUP(Q18, FusesTable, 7, FALSE) -> #N/A | R23: A | T23: MSD | Y23: =IF(ISBLANK(W23), IncompleteText, OKText) -> BLANK
A24: 13 | H24: =C24*BattCellMaxV -> 0 | J24: =H24*B24*BattCellCapacity*0.0036 -> 0 | L24: =IF(COUNTBLANK(B24:C24)+COUNTBLANK(F24:G24)=4,"",IF(COUNTBLANK(B24:C24)+COUNTBLANK(F24:G24) > 0, IncompleteText, IF(OR(H24>120, J24>6), ErrorText, OKText))) | M24: Temperature Sensors | T24: Ampacity | W24: =VLOOKUP(W23, ConnectorsTable, 5, FALSE) -> #N/A | X24: A | Y24: =IF(ISERROR(W24), IncompleteText, IF(W24 < MainFuseA, ErrorText, OKText)) -> BLANK
A25: 14 | H25: =C25*BattCellMaxV -> 0 | J25: =H25*B25*BattCellCapacity*0.0036 -> 0 | L25: =IF(COUNTBLANK(B25:C25)+COUNTBLANK(F25:G25)=4,"",IF(COUNTBLANK(B25:C25)+COUNTBLANK(F25:G25) > 0, IncompleteText, IF(OR(H25>120, J25>6), ErrorText, OKText))) | M25: Temp Sensor Location | S25: =IF(ISBLANK(Q25), IncompleteText, OKText) -> BLANK | T25: Main Connector
A26: 15 | H26: =C26*BattCellMaxV -> 0 | J26: =H26*B26*BattCellCapacity*0.0036 -> 0 | L26: =IF(COUNTBLANK(B26:C26)+COUNTBLANK(F26:G26)=4,"",IF(COUNTBLANK(B26:C26)+COUNTBLANK(F26:G26) > 0, IncompleteText, IF(OR(H26>120, J26>6), ErrorText, OKText))) | M26: Distance to cell terminal | R26: mm | S26: =IF(Q25="On cell terminal","",IF(ISBLANK(Q26),IncompleteText,IF(Q26<10,OKText,ErrorText))) -> BLANK | T26: Main Connector | Y26: =IF(ISBLANK(W26), IncompleteText, OKText) -> BLANK
A27: 16 | H27: =C27*BattCellMaxV -> 0 | J27: =H27*B27*BattCellCapacity*0.0036 -> 0 | L27: =IF(COUNTBLANK(B27:C27)+COUNTBLANK(F27:G27)=4,"",IF(COUNTBLANK(B27:C27)+COUNTBLANK(F27:G27) > 0, IncompleteText, IF(OR(H27>120, J27>6), ErrorText, OKText))) | M27: Cells sensed per sensor | R27: cell(s) | S27: =IF(ISBLANK(Q27), IncompleteText, OKText) -> BLANK | T27: Ampacity | W27: =VLOOKUP(W26, ConnectorsTable, 5, FALSE) -> #N/A | X27: A | Y27: =IF(ISERROR(W27), IncompleteText,IF(W27 < MainFuseA, ErrorText, OKText)) -> BLANK
A28: 17 | H28: =C28*BattCellMaxV -> 0 | J28: =H28*B28*BattCellCapacity*0.0036 -> 0 | L28: =IF(COUNTBLANK(B28:C28)+COUNTBLANK(F28:G28)=4,"",IF(COUNTBLANK(B28:C28)+COUNTBLANK(F28:G28) > 0, IncompleteText, IF(OR(H28>120, J28>6), ErrorText, OKText))) | M28: Thermal Contact material used | T28: Voltage | W28: =VLOOKUP(W26, ConnectorsTable, 4, FALSE) -> #N/A | X28: V | Y28: =IF(ISERROR(W28), IncompleteText,IF(W28 < MaxTSVoltage, ErrorText, OKText)) -> BLANK
A29: 18 | H29: =C29*BattCellMaxV -> 0 | J29: =H29*B29*BattCellCapacity*0.0036 -> 0 | L29: =IF(COUNTBLANK(B29:C29)+COUNTBLANK(F29:G29)=4,"",IF(COUNTBLANK(B29:C29)+COUNTBLANK(F29:G29) > 0, IncompleteText, IF(OR(H29>120, J29>6), ErrorText, OKText))) | M29: Thermal contact material datasheet | S29: =IF(ISBLANK(Q28), "", IF(ISBLANK(Q29), IncompleteText, OKText))
M30: Thermal contact material conductivity | R30: W/(m∙K) | S30: =IF(ISBLANK(Q28), "", IF(ISBLANK(Q30), IncompleteText, OKText))
M31: Thermal contact material thickness | R31: mm | S31: =IF(ISBLANK(Q28), "", IF(ISBLANK(Q31), IncompleteText, OKText))
M32: Percent of cells sensed | Q32: =SUMIF(L12:L29, "=OK", F12:F29)*CellsPerTempSensor/TotalCells*100 -> #DIV/0! | R32: % | S32: =IF(ISERROR(Q32),IncompleteText,IF(Q32<20,ErrorText,OKText)) -> BLANK
A34: Picture of Maintenance Plugs | L34: Picture of Cell Connections | U34: Picture of Temperature Sensor Location | AD34: Picture of Fuse and IRs Separation from Cells | AM34: Picture of Module Insulation between Cell Terminals and Sides of Tractive Battery Container | AV34: Picture of Insulation on Top of Module
A53: Maintenance Plug(s) Picture Shows | J53: =IF(COUNTIF(J54:J57, "="&IncompleteText), IncompleteText, IF(COUNTIF(J54:J57, "="&ErrorText), ErrorText, OKText)) -> BLANK | L53: Cell Connections Picture Shows | S53: =IF(COUNTIF(S54:S56, "="&IncompleteText), IncompleteText, IF(COUNTIF(S54:S56, "="&ErrorText), ErrorText, OKText)) -> BLANK | U53: Temperature Sensor Picture Shows | AB53: =IF(COUNTIF(AB54:AB55, "="&IncompleteText), IncompleteText, IF(COUNTIF(AB54:AB55, "="&ErrorText), ErrorText, OKText)) -> BLANK | AD53: Fuse and IRs Separation Picture Shows | AK53: =IF(COUNTIF(AK54, "="&IncompleteText), IncompleteText, IF(COUNTIF(AK54, "="&ErrorText), ErrorText, OKText)) -> BLANK | AM53: Module Insulation Picture Shows | AT53: =IF(COUNTIF(AT54, "="&IncompleteText), IncompleteText, IF(COUNTIF(AT54, "="&ErrorText), ErrorText, OKText)) -> BLANK | AV53: Module Insulation Picture Shows | BC53: =IF(COUNTIF(BC54, "="&IncompleteText), IncompleteText, IF(COUNTIF(BC54, "="&ErrorText), ErrorText, OKText)) -> BLANK
A54: Unique Configuration of plugs | J54: =IF(ISBLANK(I54),IncompleteText, IF(I54, OKText, ErrorText)) -> BLANK | L54: Bolted connections have positive locking | S54: =IF(ISBLANK(R54),IncompleteText, IF(R54, OKText, ErrorText)) -> BLANK | U54: Temp sensor in direct contact with terminal or busbar | AB54: =IF(ISBLANK(AA54),IncompleteText, IF(AA54, OKText, ErrorText)) -> BLANK | AD54: Fuse and IRs are separated from cells | AK54: =IF(ISBLANK(AJ54),IncompleteText, IF(AJ54, OKText, ErrorText)) -> BLANK | AM54: Insulation between cells and tractive battery container | AT54: =IF(ISBLANK(AS54),IncompleteText, IF(AS54, OKText, ErrorText)) -> BLANK | AV54: Insulation on top of cells (air not acceptable) | BC54: =IF(ISBLANK(BB54),IncompleteText, IF(BB54, OKText, ErrorText)) -> BLANK
A55: Non-conductive on un-necessary surface | J55: =IF(ISBLANK(I55),IncompleteText, IF(I55, OKText, ErrorText)) -> BLANK | L55: Location of overcurrent protection for parallel cells | S55: =IF($B$12=1,OKText,IF(ISBLANK(R55),IncompleteText, IF(R55, OKText, ErrorText))) -> BLANK | U55: Distance from sensor to cell negative terminal connection | AB55: =IF(ISBLANK(AA55),IncompleteText, IF(AA55, OKText, ErrorText)) -> BLANK | AD55: Additional Comments | AK55: Rules References | AM55: Additional Comments | AT55: Rules References | AV55: Additional Comments | BC55: Rules References
A56: Accessible without any additional disassembly | J56: =IF(ISBLANK(I56),IncompleteText, IF(I56, OKText, ErrorText)) -> BLANK | L56: BMS voltage sense fuse location | S56: =IF(ISBLANK(R56),IncompleteText, IF(R56, OKText, ErrorText)) -> BLANK | U56: Additional Comments | AB56: Rules References | AK56: EV.5.4.4 | AT56: EV.5.2.2.a EV.5.2.3 | BC56: EV.5.2.2.a EV.5.2.3
A57: Positive Locking | J57: =IF(ISBLANK(I57),IncompleteText, IF(I57, OKText, ErrorText)) -> BLANK | L57: Additional Comments | S57: Rules References | AB57: EV.8.5
A58: Additional Comments | J58: Rules References | S58: EV.7.4.1 EV.7.4.3 EV.8.4.3.a
J59: EV.5.3
A63: Parallel Cell Fusing | H63: =IF(B12=1, OKText, IF(COUNTIF(H64:H75, "="&IncompleteText), IncompleteText, IF(COUNTIF(H64:H75, "="&ErrorText), ErrorText, OKText))) -> BLANK | I63: Rules Referenes
A64: Source | H64: =IF(B12 <> 1, IF(ISBLANK(F64),IncompleteText,OKText), "") -> BLANK | I64: EV.7.6.3 EV.7.6.5
A65: Make/Model | H65: =IF(F64 = "Purchased", IF(ISBLANK(F65), IncompleteText, OKText), "")
...

Sheet PrechargeDischarge
A1: Status | B1: {=IF(SUM(COUNTIF(INDIRECT({"PrechargeDischarge!$F$2","PrechargeDischarge!$L$2","PrechargeDischarge!$R$2","PrechargeDischarge!$R$10"}), "="&IncompleteText)), IncompleteText, IF(SUM(COUNTIF(INDIRECT({"PrechargeDischarge!$F$2","PrechargeDischarge!$L$2","PrechargeDischarge!$R$2","PrechargeDischarge!$R$10"}), "="&ErrorText)), ErrorText, OKText))} -> BLANK
A2: Precharge | F2: =IF(COUNTIF(F3:F23, "="&IncompleteText), IncompleteText, IF(COUNTIF(F3:F23, "="&ErrorText), ErrorText, OKText)) -> BLANK | G2: Discharge | L2: =IF(COUNTIF(L3:L17, "="&IncompleteText), IncompleteText, IF(COUNTIF(L3:L17, "="&ErrorText), ErrorText, OKText)) -> BLANK | M2: Vehicle TSMP | R2: =IF(COUNTIF(R3:R8, "="&IncompleteText), IncompleteText, IF(COUNTIF(R3:R8, "="&ErrorText), ErrorText, OKText)) -> BLANK | S2: Rules References
A3: Resistor | F3: =IF(ISBLANK(D3), IncompleteText, OKText) -> BLANK | G3: Resistor | L3: =IF(ISBLANK(J3), IncompleteText, OKText) -> BLANK | M3: Resistor | R3: =IF(ISBLANK(P3), IncompleteText, OKText) -> BLANK | S3: EV.5.8.4
A4: # parallel | F4: =IF(ISBLANK(D4), IncompleteText, OKText) -> BLANK | G4: # parallel | L4: =IF(ISBLANK(J4), IncompleteText, OKText) -> BLANK | M4: # parallel | R4: =IF(ISBLANK(P4), IncompleteText, OKText) -> BLANK
A5: # series | F5: =IF(ISBLANK(D5), IncompleteText, OKText) -> BLANK | G5: # series | L5: =IF(ISBLANK(J5), IncompleteText, OKText) -> BLANK | M5: # series | R5: =IF(ISBLANK(P5), IncompleteText, OKText) -> BLANK
A6: Resistance | D6: =VLOOKUP(D3, ResistorsTable, 5, )*D5/D4 -> #N/A | E6: Ohms | G6: Resistance | J6: =VLOOKUP(J3, ResistorsTable, 5, )*J5/J4 -> #N/A | K6: Ohms | M6: Resistance | P6: =VLOOKUP(P3, ResistorsTable, 5, )*P5/P4 -> #N/A | Q6: Ohms | R6: =IF(MaxTSVoltage<=200,IF(P6=5000, OKText, ErrorText),IF(MaxTSVoltage > 400, IF(P6=15000, OKText, ErrorText), IF(P6=10000, OKText, ErrorText))) -> #N/A
A7: Cont power | D7: =VLOOKUP(D3, ResistorsTable, 6, FALSE)*D4*D5 -> #N/A | E7: W | G7: Cont power | J7: =VLOOKUP(J3, ResistorsTable, 6, FALSE)*J4*J5 -> #N/A | K7: W | M7: Cont power | P7: =VLOOKUP(P3, ResistorsTable, 6, FALSE)*P5*P4 -> #N/A | Q7: W | R7: =IF(P7<(MaxTSVoltage/2)^2/P6, ErrorText, OKText) -> #N/A
A8: power @15 sec | D8: =VLOOKUP(D3, ResistorsTable, 7, FALSE)*D4*D5 -> #N/A | E8: W | G8: power @15 sec | J8: =VLOOKUP(J3, ResistorsTable, 7, FALSE)*J4*J5 -> #N/A | K8: W | L8: =IF(J8<MaxTSVoltage^2/DischargeRes, ErrorText, OKText) -> #N/A | M8: Voltage | P8: =VLOOKUP(P3, ResistorsTable, 4, FALSE)*P5 -> #N/A | Q8: V | R8: =IF(P8<(MaxTSVoltage/2), ErrorText, OKText) -> #N/A
A9: Voltage | D9: =VLOOKUP(D3, ResistorsTable, 4, FALSE)*D5 -> #N/A | E9: V | F9: =IF(D9<MaxTSVoltage, ErrorText, OKText) -> #N/A | G9: Voltage | J9: =VLOOKUP(J3, ResistorsTable, 4, FALSE)*J5 -> #N/A | K9: V | L9: =IF(J9<MaxTSVoltage, ErrorText, OKText) -> #N/A
A10: Bus Capacitance | E10: mF | F10: =IF(ISBLANK(BusCap), IncompleteText, OKText) -> BLANK | G10: Peak power | J10: =MaxTSVoltage^2/DischargeRes -> #N/A | K10: W | M10: Charger TSMP | R10: =IF(COUNTIF(R11:R17, "="&IncompleteText), IncompleteText, IF(COUNTIF(R11:R17, "="&ErrorText), ErrorText, OKText)) -> BLANK | S10: Rules References
A11: End of precharge | F11: =IF(ISBLANK(D11), IncompleteText, OKText) -> BLANK | G11: Peak current | J11: =MaxTSVoltage/DischargeRes -> #N/A | K11: A | M11: Same parts as vehicle TSMP? | R11: =IF(ISBLANK(P11), IncompleteText, OKText) -> BLANK | S11: EV.5.8.2; EV.5.8.4
G12: Discharge time (to 60V) | J12: =-LN(60/MaxTSVoltage)*DischargeRes*(BusCap/1000) -> #DIV/0! | K12: s | L12: =IF(J12>5, ErrorText, OKText) -> #DIV/0! | M12: Resistor | R12: =IF(P$11="No",IF(ISBLANK(P12), IncompleteText, OKText),"")
A13: delta V | E13: V | F13: =IF(D11<>"Delta Voltage", "", IF(ISBLANK(D13), IncompleteText, IF(D13 > MaxTSVoltage*0.1, ErrorText, OKText))) | G13: Relay | L13: =IF(ISBLANK(J13), IncompleteText, OKText) -> BLANK | M13: # parallel | R13: =IF(P$11="No",IF(ISBLANK(P13), IncompleteText, OKText),"")
A14: ending ratio | E14: % | F14: =IF(D11<>"Ratio", "", IF(ISBLANK(D14), IncompleteText, IF(D14 < 90, ErrorText, OKText))) | G14: Relay voltage rating | J14: =VLOOKUP(J13, ContactorsTable, 4, FALSE) -> #N/A | K14: V | L14: =IF(J14<MaxTSVoltage, ErrorText, OKText) -> #N/A | M14: # series | R14: =IF(P$11="No",IF(ISBLANK(P14), IncompleteText, OKText),"")
A15: Peak power | D15: =MaxTSVoltage^2/PrechargeRes -> #N/A | E15: W | G15: Relay current rating | J15: =MIN(VLOOKUP(J13, ContactorsTable, 5, FALSE),VLOOKUP(J13, ContactorsTable, 6, FALSE)) -> #N/A | K15: A | L15: =IF(J15<J11, ErrorText, OKText) -> #N/A | M15: Resistance | P15: =VLOOKUP(P12, ResistorsTable, 5, )*P14/P13 -> #N/A | Q15: Ohms | R15: =IF(P$11="No",IF(MaxTSVoltage<=200,IF(P15=5000, OKText, ErrorText),IF(MaxTSVoltage > 400, IF(P15=15000, OKText, ErrorText), IF(P15=10000, OKText, ErrorText))),"")
A16: Peak current | D16: =MaxTSVoltage/PrechargeRes -> #N/A | E16: A | G16: Relay power rating | J16: =VLOOKUP(J13, ContactorsTable, 7, FALSE) -> #N/A | K16: W | L16: =IF(J16<J10, ErrorText, OKText) -> #N/A | M16: Cont power | P16: =VLOOKUP(P12, ResistorsTable, 6, FALSE)*P14*P13 -> #N/A | Q16: W | R16: =IF(P$11="No",IF(P16<(MaxTSVoltage/2)^2/P15, ErrorText, OKText),"")
A17: time to 90% | D17: =-LN(0.1)*(BusCap/1000)*PrechargeRes -> #N/A | E17: sec | G17: Normal State | J17: =VLOOKUP(J13, ContactorsTable, 9, FALSE) -> #N/A | L17: =IF(J17<> "NC", ErrorText, OKText) -> #N/A | M17: Voltage | P17: =VLOOKUP(P12, ResistorsTable, 4, FALSE)*P14 -> #N/A | Q17: V | R17: =IF(P$11="No",IF(P17<(MaxTSVoltage/2), ErrorText, OKText),"")
A18: Precharge Res Energy to 90% | D18: =MaxTSVoltage^2*(BusCap/1000)/2*(1-EXP(-D17*2/(PrechargeRes*(BusCap/1000)))) -> #N/A | E18: J | G18: Rules References
A19: Average Power | D19: =D18/D17 -> #N/A | E19: W | G19: EV.5.6; EV.8.2.2.c
A20: Relay | F20: =IF(ISBLANK(D20), IncompleteText, OKText) -> BLANK
A21: Relay voltage rating | D21: =VLOOKUP(D20, ContactorsTable, 4, FALSE) -> #N/A | E21: V | F21: =IF(D21<MaxTSVoltage, ErrorText, OKText) -> #N/A
A22: Relay current rating | D22: =MIN(VLOOKUP(D20, ContactorsTable, 5, FALSE),VLOOKUP(D20, ContactorsTable, 6, FALSE)) -> #N/A | E22: A | F22: =IF(D22<D16, ErrorText, OKText) -> #N/A
A23: Relay power rating | D23: =VLOOKUP(D20, ContactorsTable, 7, FALSE) -> #N/A | E23: W | F23: =IF(D23<D15, ErrorText, OKText) -> #N/A
A25: Additional Comments

Sheet Shutdown Circuit
A1: Status | B1: {=IF(SUM(COUNTIF(INDIRECT({"'Shutdown Circuit'!$F$2","'Shutdown Circuit'!$M$2","'Shutdown Circuit'!$K$36","'Shutdown Circuit'!$W$36","'Shutdown Circuit'!$W$75"}), "="&IncompleteText)), IncompleteText, IF(SUM(COUNTIF(INDIRECT({"'Shutdown Circuit'!$F$2","'Shutdown Circuit'!$M$2","'Shutdown Circuit'!$K$36","'Shutdown Circuit'!$W$36","'Shutdown Circuit'!$W$75"}), "="&ErrorText)), ErrorText, OKText))} -> BLANK
A2: IMD | F2: =IF(COUNTIF(F4:F5, "="&IncompleteText), IncompleteText, IF(COUNTIF(F4:F5, "="&ErrorText), ErrorText, OKText)) -> BLANK | H2: BSPD | M2: =IF(COUNTIF(M4:M8, "="&IncompleteText), IncompleteText, IF(COUNTIF(M4:M8, "="&ErrorText), ErrorText, OKText)) -> BLANK
A3: Rules Reference | D3: EV.8.6 | H3: Rules Reference | K3: EV.8.7
A4: Make/Model | F4: =IF(ISBLANK(D4), IncompleteText, OKText) -> BLANK | H4: Current Sensor Make/Model | M4: =IF(ISBLANK(K4), IncompleteText, OKText) -> BLANK
A5: Setpoint | E5: kΩ | F5: =IF(ISBLANK(D5), IncompleteText, IF(D5<(MaxTSVoltage*0.5), ErrorText, OKText)) -> BLANK | H5: Current Sensor Datasheet | M5: =IF(ISBLANK(K5), IncompleteText, OKText) -> BLANK
H6: Trip Current | L6: A | M6: =IF(ISBLANK(K6),IncompleteText,IF(K6>(5000/NominalTSVoltage),ErrorText,OKText)) -> BLANK
H7: Sensor Output @ Trip Current | L7: V | M7: =IF(ISBLANK(K7), IncompleteText, OKText) -> BLANK
H8: Accuracy @ Trip Current | L8: A | M8: =IF(ISBLANK(K8), IncompleteText, OKText) -> BLANK
A10: Shutdown Circuit Schematic | M10: BSPD System Schematic
A36: Shutdown Circuit Schematic Shows | K36: =IF(COUNTIF(K38:K63, "="&IncompleteText), IncompleteText, IF(COUNTIF(K38:K63, "="&ErrorText), ErrorText, OKText)) -> BLANK | M36: BSPD System Schematic Shows | W36: =IF(COUNTIF(W38:W42, "="&IncompleteText), IncompleteText, IF(COUNTIF(W38:W42, "="&ErrorText), ErrorText, OKText)) -> BLANK
A37: Rules References
C38: GLV Battery | D38: GLV Battery | E38: GLV Battery | F38: GLV Battery | G38: GLV Battery | H38: GLV Battery | I38: GLV Battery | K38: =IF(ISBLANK(J38),IncompleteText, IF(J38, OKText, ErrorText)) -> BLANK | M38: BSPD Current Sensor input open/short circuit protection | W38: =IF(ISBLANK(V38),IncompleteText, IF(V38, OKText, ErrorText)) -> BLANK
A39: T.9.2.2 | B39: T.9.2.2 | C39: GLV Fuse | D39: GLV Fuse | E39: GLV Fuse | F39: GLV Fuse | G39: GLV Fuse | H39: GLV Fuse | I39: GLV Fuse | K39: =IF(ISBLANK(J39),IncompleteText, IF(J39, OKText, ErrorText)) -> BLANK | M39: BSPD Brake Sensor input open/short circuit protection | W39: =IF(ISBLANK(V39),IncompleteText, IF(V39, OKText, ErrorText)) -> BLANK
A40: EV.8.9.2 | B40: EV.7.9.2 | C40: GLVMS | D40: GLVMS | E40: GLVMS | F40: GLVMS | G40: GLVMS | H40: GLVMS | I40: GLVMS | K40: =IF(ISBLANK(J40),IncompleteText, IF(J40, OKText, ErrorText)) -> BLANK | M40: Shutdown circuit powerstage | W40: =IF(ISBLANK(V40),IncompleteText, IF(V40, OKText, ErrorText)) -> BLANK
A41: EV.8.9.2.a | B41: EV.7.9.2.a | C41: GLVMS is first switch | D41: GLVMS is first switch | E41: GLVMS is first switch | F41: GLVMS is first switch | G41: GLVMS is first switch | H41: GLVMS is first switch | I41: GLVMS is first switch | K41: =IF(ISBLANK(J41),IncompleteText, IF(J41, OKText, ErrorText)) -> BLANK | M41: Standard schematic symbols used | W41: =IF(ISBLANK(V41),IncompleteText, IF(V41, OKText, ErrorText)) -> BLANK
C42: HV DC/DC converter GLV connection (if applicable) | D42: HV DC/DC converter GLV connection (if applicable) | E42: HV DC/DC converter GLV connection (if applicable) | F42: HV DC/DC converter GLV connection (if applicable) | G42: HV DC/DC converter GLV connection (if applicable) | H42: HV DC/DC converter GLV connection (if applicable) | I42: HV DC/DC converter GLV connection (if applicable) | K42: =IF(ISBLANK(J42),IncompleteText,IF(OR(J42=TRUE,J42="N/A"),OKText,ErrorText)) -> BLANK | M42: Schematic signals are clearly labeled (e.g., “Brake High,” “BSPD Fault,” etc.) | W42: =IF(ISBLANK(V42),IncompleteText, IF(V42, OKText, ErrorText)) -> BLANK
A43: EV.8.6 | B43: EV.7.6 | C43: IMD | D43: IMD | E43: IMD | F43: IMD | G43: IMD | H43: IMD | I43: IMD | K43: =IF(ISBLANK(J43),IncompleteText, IF(J43, OKText, ErrorText)) -> BLANK | M43: Additional Comments | V43: Rules References
A44: EV.8.3 | B44: EV.7.3 | C44: BMS | D44: BMS | E44: BMS | F44: BMS | G44: BMS | H44: BMS | I44: BMS | K44: =IF(ISBLANK(J44),IncompleteText, IF(J44, OKText, ErrorText)) -> BLANK | V44: EV.8.7
A45: EV.8.7 | B45: EV.7.7 | C45: BSPD | D45: BSPD | E45: BSPD | F45: BSPD | G45: BSPD | H45: BSPD | I45: BSPD | K45: =IF(ISBLANK(J45),IncompleteText, IF(J45, OKText, ErrorText)) -> BLANK
A46: EV.8.1.5 | B46: EV.7.1.4 | C46: IMD, BMS, BSPD have independent power stages | D46: IMD, BMS, BSPD have independent power stages | E46: IMD, BMS, BSPD have independent power stages | F46: IMD, BMS, BSPD have independent power stages | G46: IMD, BMS, BSPD have independent power stages | H46: IMD, BMS, BSPD have independent power stages | I46: IMD, BMS, BSPD have independent power stages | K46: =IF(ISBLANK(J46),IncompleteText, IF(J46, OKText, ErrorText)) -> BLANK
A47: T.9.4 | B47: T.9.4 | C47: Inertia Switch | D47: Inertia Switch | E47: Inertia Switch | F47: Inertia Switch | G47: Inertia Switch | H47: Inertia Switch | I47: Inertia Switch | K47: =IF(ISBLANK(J47),IncompleteText, IF(J47, OKText, ErrorText)) -> BLANK
A48: EV.8.10.4 | B48: EV.7.10.4 | C48: 1 Cockpit Shutdown Button | D48: 1 Cockpit Shutdown Button | E48: 1 Cockpit Shutdown Button | F48: 1 Cockpit Shutdown Button | G48: 1 Cockpit Shutdown Button | H48: 1 Cockpit Shutdown Button | I48: 1 Cockpit Shutdown Button | K48: =IF(ISBLANK(J48),IncompleteText, IF(J48, OKText, ErrorText)) -> BLANK
A49: EV.8.10.3 | B49: EV.7.10.3 | C49: 2 Side Shutdown Buttons | D49: 2 Side Shutdown Buttons | E49: 2 Side Shutdown Buttons | F49: 2 Side Shutdown Buttons | G49: 2 Side Shutdown Buttons | H49: 2 Side Shutdown Buttons | I49: 2 Side Shutdown Buttons | K49: =IF(ISBLANK(J49),IncompleteText, IF(J49, OKText, ErrorText)) -> BLANK | M49: Ready To Move Light Schematic
A50: T.3.3 | B50: T.3.3 | C50: Brake Over Travel Switch (BOTS) | D50: Brake Over Travel Switch (BOTS) | E50: Brake Over Travel Switch (BOTS) | F50: Brake Over Travel Switch (BOTS) | G50: Brake Over Travel Switch (BOTS) | H50: Brake Over Travel Switch (BOTS) | I50: Brake Over Travel Switch (BOTS) | K50: =IF(ISBLANK(J50),IncompleteText, IF(J50, OKText, ErrorText)) -> BLANK
A51: EV.5.5.3 | B51: EV.5.5.3 | C51: MSD Interlock | D51: MSD Interlock | E51: MSD Interlock | F51: MSD Interlock | G51: MSD Interlock | H51: MSD Interlock | I51: MSD Interlock | K51: =IF(ISBLANK(J51),IncompleteText, IF(J51, OKText, ErrorText)) -> BLANK
A52: EV.3.2 | B52: EV.3.2 | C52: Energy Meter interlock | D52: Energy Meter interlock | E52: Energy Meter interlock | F52: Energy Meter interlock | G52: Energy Meter interlock | H52: Energy Meter interlock | I52: Energy Meter interlock | K52: =IF(ISBLANK(J52),IncompleteText, IF(J52, OKText, ErrorText)) -> BLANK
A53: EV.4.1.3.a | B53: EV.4.1.3.a | C53: Outboard Wheel Motor Interlocks (if applicable) | D53: Outboard Wheel Motor Interlocks (if applicable) | E53: Outboard Wheel Motor Interlocks (if applicable) | F53: Outboard Wheel Motor Interlocks (if applicable) | G53: Outboard Wheel Motor Interlocks (if applicable) | H53: Outboard Wheel Motor Interlocks (if applicable) | I53: Outboard Wheel Motor Interlocks (if applicable) | K53: =IF(ISBLANK(J53),IncompleteText,IF(OR(J53=TRUE,J53="N/A"),OKText,ErrorText)) -> BLANK
A54: EV.7.4.4 | B54: EV.5.9 | C54: Interlocks on TS connectors outside of an enclosure | D54: Interlocks on TS connectors outside of an enclosure | E54: Interlocks on TS connectors outside of an enclosure | F54: Interlocks on TS connectors outside of an enclosure | G54: Interlocks on TS connectors outside of an enclosure | H54: Interlocks on TS connectors outside of an enclosure | I54: Interlocks on TS connectors outside of an enclosure | K54: =IF(ISBLANK(J54),IncompleteText, IF(J54, OKText, ErrorText)) -> BLANK
A55: EV.8.9.3 | B55: EV.7.9.3 | C55: TSMS | D55: TSMS | E55: TSMS | F55: TSMS | G55: TSMS | H55: TSMS | I55: TSMS | K55: =IF(ISBLANK(J55),IncompleteText, IF(J55, OKText, ErrorText)) -> BLANK
A56: EV.8.9.3.b | B56: EV.7.9.3.b | C56: TSMS is last switch (excluding precharge circuitry or interlocks) | D56: TSMS is last switch (excluding precharge circuitry or interlocks) | E56: TSMS is last switch (excluding precharge circuitry or interlocks) | F56: TSMS is last switch (excluding precharge circuitry or interlocks) | G56: TSMS is last switch (excluding precharge circuitry or interlocks) | H56: TSMS is last switch (excluding precharge circuitry or interlocks) | I56: TSMS is last switch (excluding precharge circuitry or interlocks) | K56: =IF(ISBLANK(J56),IncompleteText, IF(J56, OKText, ErrorText)) -> BLANK
A57: EV.8.1.2; EV.8.1.6 | B57: EV.7.1.2; EV.7.1.5 | C57: Precharge Contactor coil | D57: Precharge Contactor coil | E57: Precharge Contactor coil | F57: Precharge Contactor coil | G57: Precharge Contactor coil | H57: Precharge Contactor coil | I57: Precharge Contactor coil | K57: =IF(ISBLANK(J57),IncompleteText, IF(J57, OKText, ErrorText)) -> BLANK
A58: EV.8.1.2; EV.8.1.6 | B58: EV.7.1.2; EV.7.1.5 | C58: Positive IR coil | D58: Positive IR coil | E58: Positive IR coil | F58: Positive IR coil | G58: Positive IR coil | H58: Positive IR coil | I58: Positive IR coil | K58: =IF(ISBLANK(J58),IncompleteText, IF(J58, OKText, ErrorText)) -> BLANK
A59: EV.8.1.2; EV.8.1.6 | B59: EV.7.1.2; EV.7.1.5 | C59: Negative IR coil | D59: Negative IR coil | E59: Negative IR coil | F59: Negative IR coil | G59: Negative IR coil | H59: Negative IR coil | I59: Negative IR coil | K59: =IF(ISBLANK(J59),IncompleteText, IF(J59, OKText, ErrorText)) -> BLANK
A60: EV.5.6.3.a | B60: EV.5.6.3.a | C60: Discharge Contactor coil | D60: Discharge Contactor coil | E60: Discharge Contactor coil | F60: Discharge Contactor coil | G60: Discharge Contactor coil | H60: Discharge Contactor coil | I60: Discharge Contactor coil | K60: =IF(ISBLANK(J60),IncompleteText, IF(J60, OKText, ErrorText)) -> BLANK
C61: Wire Gauge | D61: Wire Gauge | E61: Wire Gauge | F61: Wire Gauge | G61: Wire Gauge | H61: Wire Gauge | I61: Wire Gauge | K61: =IF(ISBLANK(J61),IncompleteText, IF(J61, OKText, ErrorText)) -> BLANK
C62: Uses proper electrical schematic symbols | D62: Uses proper electrical schematic symbols | E62: Uses proper electrical schematic symbols | F62: Uses proper electrical schematic symbols | G62: Uses proper electrical schematic symbols | H62: Uses proper electrical schematic symbols | I62: Uses proper electrical schematic symbols | K62: =IF(ISBLANK(J62),IncompleteText, IF(J62, OKText, ErrorText)) -> BLANK
C63: Labels/text are readable (zooming in is acceptable) | D63: Labels/text are readable (zooming in is acceptable) | E63: Labels/text are readable (zooming in is acceptable) | F63: Labels/text are readable (zooming in is acceptable) | G63: Labels/text are readable (zooming in is acceptable) | H63: Labels/text are readable (zooming in is acceptable) | I63: Labels/text are readable (zooming in is acceptable) | K63: =IF(ISBLANK(J63),IncompleteText, IF(J63, OKText, ErrorText)) -> BLANK
A64: Additional Comments | J64: Rules References
J65: EV.8.1 EV.8.2
M77: Ready to Move Light Schematic Shows | W77: =IF(COUNTIF(W78:W84, "="&IncompleteText), IncompleteText, IF(COUNTIF(W78:W84, "="&ErrorText), ErrorText, OKText)) -> BLANK
...

Sheet Charging
A1: Status | B1: {=IF(SUM(COUNTIF(INDIRECT({"Charging!$F$2","Charging!$H$32","Charging!$Q$32"}), "="&IncompleteText)), IncompleteText, IF(SUM(COUNTIF(INDIRECT({"Charging!$F$2","Charging!$H$32","Charging!$Q$32"}), "="&ErrorText)), ErrorText, OKText))} -> BLANK
A2: Charger | F2: =IF(COUNTIF(F3:F11, "="&IncompleteText), IncompleteText, IF(COUNTIF(F3:F11, "="&ErrorText), ErrorText, OKText)) -> BLANK | H2: Additional Comments
A3: Make | F3: =IF(ISBLANK(D3), IncompleteText, OKText) -> BLANK
A4: Model | F4: =IF(ISBLANK(D4), IncompleteText, OKText) -> BLANK
A5: Datasheet | F5: =IF(ISBLANK(D5), IncompleteText, OKText) -> BLANK
A6: Input Voltage | E6: V | F6: =IF(ISBLANK(D6), IncompleteText, OKText) -> BLANK
A7: Input Current | E7: A | F7: =IF(ISBLANK(D7), IncompleteText, OKText) -> BLANK
A8: Output Voltage | E8: V | F8: =IF(ISBLANK(D8), IncompleteText, OKText) -> BLANK
A9: Output Current | E9: A | F9: =IF(ISBLANK(D9), IncompleteText, OKText) -> BLANK
A10: Power | E10: kW | F10: =IF(ISBLANK(D10), IncompleteText, OKText) -> BLANK
A11: Input to Output isolation | F11: =IF(ISBLANK(D11), IncompleteText, OKText) -> BLANK
A13: Charging Tractive System Schematic | J13: Charging Shutdown Circuit
A32: Charging Tractive System Schematic Shows | H32: =IF(COUNTIF(H34:H39, "="&IncompleteText), IncompleteText, IF(COUNTIF(H34:H39, "="&ErrorText), ErrorText, OKText)) -> BLANK | J32: Charging Shutdown Circuit Shows | Q32: =IF(COUNTIF(Q34:Q39, "="&IncompleteText), IncompleteText, IF(COUNTIF(Q34:Q39, "="&ErrorText), ErrorText, OKText)) -> BLANK
A33: Rules References | J33: Rules References
A34: EV.7.6 | C34: Fuse | H34: =IF(ISBLANK(G34),IncompleteText, IF(G34, OKText, ErrorText)) -> BLANK | J34: EV.9.3 | L34: IMD Control and Powerstage | Q34: =IF(ISBLANK(P34),IncompleteText, IF(P34, OKText, ErrorText)) -> BLANK
C35: Connectors | H35: =IF(ISBLANK(G35),IncompleteText, IF(G35, OKText, ErrorText)) -> BLANK | J35: EV.9.3 | L35: BMS | Q35: =IF(ISBLANK(P35),IncompleteText, IF(P35, OKText, ErrorText)) -> BLANK
C36: Wire Gauge | H36: =IF(ISBLANK(G36),IncompleteText, IF(G36, OKText, ErrorText)) -> BLANK | J36: EV.9.2.7 | L36: Charger Shutdown Button | Q36: =IF(ISBLANK(P36),IncompleteText, IF(P36, OKText, ErrorText)) -> BLANK
A37: EV.9.4.1 | C37: IMD | H37: =IF(ISBLANK(G37),IncompleteText, IF(G37, OKText, ErrorText)) -> BLANK | J37: EV.9.4 | L37: IRs | Q37: =IF(ISBLANK(P37),IncompleteText, IF(P37, OKText, ErrorText)) -> BLANK
A38: EV.9.4.2 | C38: IRs | H38: =IF(ISBLANK(G38),IncompleteText, IF(G38, OKText, ErrorText)) -> BLANK | J38: EV.9.2.4 | L38: Charge Connector Interlock | Q38: =IF(ISBLANK(P38),IncompleteText, IF(P38, OKText, ErrorText)) -> BLANK
A39: EV.9.2.6 | C39: TSMPs | H39: =IF(ISBLANK(G39),IncompleteText, IF(G39, OKText, ErrorText)) -> BLANK | J39: EV.9.4.2.c | L39: Charge Control (CAN, Enable, etc.) | Q39: =IF(ISBLANK(P39),IncompleteText, IF(P39, OKText, ErrorText)) -> BLANK
A40: Additional Comments | J40: Additional Comments

Sheet Torque Security
A1: Status | B1: =IF(SUM(COUNTIF(INDIRECT({"'Torque Security'!$F$2","'Torque Security'!$S$2"}), "="&IncompleteText)), IncompleteText, IF(SUM(COUNTIF(INDIRECT({"'Torque Security'!$F$2","'Torque Security'!$S$2"}), "="&ErrorText)), ErrorText, OKText)) -> BLANK
A2: APPS Sensor Transfer function | F2: =IF(COUNTIF(F4:F11, "="&IncompleteText), IncompleteText, IF(COUNTIF(F4:F11, "="&ErrorText), ErrorText, OKText)) -> BLANK | H2: Torque Control Path Security Checks | S2: =IF(COUNTIF(S6:S11, "="&IncompleteText), IncompleteText, IF(COUNTIF(S6:S11, "="&ErrorText), ErrorText, OKText)) -> BLANK
A3: Rules Reference | C3: T.4.2.3
A4: T.4.2.3 part 3 check | F4: =IF(COUNTIF(F6:F11, "="&IncompleteText), "",IF(MIN(D51:D131,G51:G131)>=0.1,OKText,ErrorText)) | H4: Source Device | J4: Destination Device | L4: Communication | M4: Redundant | N4: Out Of Range | O4: Correlation | P4: Checksum | Q4: Timeout | R4: Other | T4: Additional Comments
A5: Position | B5: APPS1 Output [V] | D5: APPS2 Output [V]
A6: 0 | F6: =IF(OR(ISBLANK(B6),ISBLANK(D6)), IncompleteText, OKText) -> BLANK | H6: APPS | S6: =IF(COUNTBLANK(J6:L6)>1, IncompleteText, OKText) -> BLANK
A7: 0.2 | F7: =IF(OR(ISBLANK(B7),ISBLANK(D7)),IncompleteText,IF(OR(AND(_xlfn.XOR(B7<D7,B6<D6),B6<>D6),B7=D7),ErrorText,OKText)) -> BLANK | H7: =IF(ISBLANK(J6),"",J6) | S7: =IF(ISBLANK(J7), "", IF(ISBLANK(L7), IncompleteText, OKText))
A8: 0.4 | F8: =IF(OR(ISBLANK(B8),ISBLANK(D8)), IncompleteText, IF(OR(_xlfn.XOR(B8<D8,B7<D7),B8=D8), ErrorText, OKText)) -> BLANK | H8: =IF(ISBLANK(J7),"",J7) | S8: =IF(ISBLANK(J8), "", IF(ISBLANK(L8), IncompleteText, OKText))
A9: 0.6 | F9: =IF(OR(ISBLANK(B9),ISBLANK(D9)), IncompleteText, IF(OR(_xlfn.XOR(B9<D9,B8<D8),B9=D9), ErrorText, OKText)) -> BLANK | H9: =IF(ISBLANK(J8),"",J8) | S9: =IF(ISBLANK(J9), "", IF(ISBLANK(L9), IncompleteText, OKText))
A10: 0.8 | F10: =IF(OR(ISBLANK(B10),ISBLANK(D10)), IncompleteText, IF(OR(_xlfn.XOR(B10<D10,B9<D9),B10=D10), ErrorText, OKText)) -> BLANK | H10: =IF(ISBLANK(J9),"",J9) | S10: =IF(ISBLANK(J10), "", IF(ISBLANK(L10), IncompleteText, OKText))
A11: 1 | F11: =IF(OR(ISBLANK(B11),ISBLANK(D11)), IncompleteText, IF(OR(_xlfn.XOR(B11<D11,B10<D10),B11=D11), ErrorText, OKText)) -> BLANK | H11: =IF(ISBLANK(J10),"",J10) | S11: =IF(ISBLANK(J11), "", IF(ISBLANK(L11), IncompleteText, OKText))
A30: Position | B30: APPS1 output | C30: APPS2 position at APPS1 output | D30: Delta | E30: APPS2 output | F30: APPS1 position at APPS2 output | G30: Delta
A31: 0 | B31: =_xlfn.FORECAST.LINEAR(A31,$B$6:$B$11,$A$6:$A$11) -> #DIV/0! | C31: =_xlfn.FORECAST.LINEAR(B31,$A$6:$A$11,$D$6:$D$11) -> #DIV/0! | D31: =ABS(C31-A31) -> #DIV/0! | E31: =_xlfn.FORECAST.LINEAR(A31,$D$6:$D$11,$A$6:$A$11) -> #DIV/0! | F31: =_xlfn.FORECAST.LINEAR(E31,$A$6:$A$11,$B$6:$B$11) -> #DIV/0! | G31: =ABS(F31-A31) -> #DIV/0!
A32: 0.01 | B32: =_xlfn.FORECAST.LINEAR(A32,$B$6:$B$11,$A$6:$A$11) -> #DIV/0! | C32: =_xlfn.FORECAST.LINEAR(B32,$A$6:$A$11,$D$6:$D$11) -> #DIV/0! | D32: =ABS(C32-A32) -> #DIV/0! | E32: =_xlfn.FORECAST.LINEAR(A32,$D$6:$D$11,$A$6:$A$11) -> #DIV/0! | F32: =_xlfn.FORECAST.LINEAR(E32,$A$6:$A$11,$B$6:$B$11) -> #DIV/0! | G32: =ABS(F32-A32) -> #DIV/0!
A33: 0.02 | B33: =_xlfn.FORECAST.LINEAR(A33,$B$6:$B$11,$A$6:$A$11) -> #DIV/0! | C33: =_xlfn.FORECAST.LINEAR(B33,$A$6:$A$11,$D$6:$D$11) -> #DIV/0! | D33: =ABS(C33-A33) -> #DIV/0! | E33: =_xlfn.FORECAST.LINEAR(A33,$D$6:$D$11,$A$6:$A$11) -> #DIV/0! | F33: =_xlfn.FORECAST.LINEAR(E33,$A$6:$A$11,$B$6:$B$11) -> #DIV/0! | G33: =ABS(F33-A33) -> #DIV/0!
A34: 0.03 | B34: =_xlfn.FORECAST.LINEAR(A34,$B$6:$B$11,$A$6:$A$11) -> #DIV/0! | C34: =_xlfn.FORECAST.LINEAR(B34,$A$6:$A$11,$D$6:$D$11) -> #DIV/0! | D34: =ABS(C34-A34) -> #DIV/0! | E34: =_xlfn.FORECAST.LINEAR(A34,$D$6:$D$11,$A$6:$A$11) -> #DIV/0! | F34: =_xlfn.FORECAST.LINEAR(E34,$A$6:$A$11,$B$6:$B$11) -> #DIV/0! | G34: =ABS(F34-A34) -> #DIV/0!
A35: 0.04 | B35: =_xlfn.FORECAST.LINEAR(A35,$B$6:$B$11,$A$6:$A$11) -> #DIV/0! | C35: =_xlfn.FORECAST.LINEAR(B35,$A$6:$A$11,$D$6:$D$11) -> #DIV/0! | D35: =ABS(C35-A35) -> #DIV/0! | E35: =_xlfn.FORECAST.LINEAR(A35,$D$6:$D$11,$A$6:$A$11) -> #DIV/0! | F35: =_xlfn.FORECAST.LINEAR(E35,$A$6:$A$11,$B$6:$B$11) -> #DIV/0! | G35: =ABS(F35-A35) -> #DIV/0!
A36: 0.05 | B36: =_xlfn.FORECAST.LINEAR(A36,$B$6:$B$11,$A$6:$A$11) -> #DIV/0! | C36: =_xlfn.FORECAST.LINEAR(B36,$A$6:$A$11,$D$6:$D$11) -> #DIV/0! | D36: =ABS(C36-A36) -> #DIV/0! | E36: =_xlfn.FORECAST.LINEAR(A36,$D$6:$D$11,$A$6:$A$11) -> #DIV/0! | F36: =_xlfn.FORECAST.LINEAR(E36,$A$6:$A$11,$B$6:$B$11) -> #DIV/0! | G36: =ABS(F36-A36) -> #DIV/0!
A37: 0.06 | B37: =_xlfn.FORECAST.LINEAR(A37,$B$6:$B$11,$A$6:$A$11) -> #DIV/0! | C37: =_xlfn.FORECAST.LINEAR(B37,$A$6:$A$11,$D$6:$D$11) -> #DIV/0! | D37: =ABS(C37-A37) -> #DIV/0! | E37: =_xlfn.FORECAST.LINEAR(A37,$D$6:$D$11,$A$6:$A$11) -> #DIV/0! | F37: =_xlfn.FORECAST.LINEAR(E37,$A$6:$A$11,$B$6:$B$11) -> #DIV/0! | G37: =ABS(F37-A37) -> #DIV/0!
A38: 0.07 | B38: =_xlfn.FORECAST.LINEAR(A38,$B$6:$B$11,$A$6:$A$11) -> #DIV/0! | C38: =_xlfn.FORECAST.LINEAR(B38,$A$6:$A$11,$D$6:$D$11) -> #DIV/0! | D38: =ABS(C38-A38) -> #DIV/0! | E38: =_xlfn.FORECAST.LINEAR(A38,$D$6:$D$11,$A$6:$A$11) -> #DIV/0! | F38: =_xlfn.FORECAST.LINEAR(E38,$A$6:$A$11,$B$6:$B$11) -> #DIV/0! | G38: =ABS(F38-A38) -> #DIV/0!
A39: 0.08 | B39: =_xlfn.FORECAST.LINEAR(A39,$B$6:$B$11,$A$6:$A$11) -> #DIV/0! | C39: =_xlfn.FORECAST.LINEAR(B39,$A$6:$A$11,$D$6:$D$11) -> #DIV/0! | D39: =ABS(C39-A39) -> #DIV/0! | E39: =_xlfn.FORECAST.LINEAR(A39,$D$6:$D$11,$A$6:$A$11) -> #DIV/0! | F39: =_xlfn.FORECAST.LINEAR(E39,$A$6:$A$11,$B$6:$B$11) -> #DIV/0! | G39: =ABS(F39-A39) -> #DIV/0!
A40: 0.09 | B40: =_xlfn.FORECAST.LINEAR(A40,$B$6:$B$11,$A$6:$A$11) -> #DIV/0! | C40: =_xlfn.FORECAST.LINEAR(B40,$A$6:$A$11,$D$6:$D$11) -> #DIV/0! | D40: =ABS(C40-A40) -> #DIV/0! | E40: =_xlfn.FORECAST.LINEAR(A40,$D$6:$D$11,$A$6:$A$11) -> #DIV/0! | F40: =_xlfn.FORECAST.LINEAR(E40,$A$6:$A$11,$B$6:$B$11) -> #DIV/0! | G40: =ABS(F40-A40) -> #DIV/0!
A41: 0.1 | B41: =_xlfn.FORECAST.LINEAR(A41,$B$6:$B$11,$A$6:$A$11) -> #DIV/0! | C41: =_xlfn.FORECAST.LINEAR(B41,$A$6:$A$11,$D$6:$D$11) -> #DIV/0! | D41: =ABS(C41-A41) -> #DIV/0! | E41: =_xlfn.FORECAST.LINEAR(A41,$D$6:$D$11,$A$6:$A$11) -> #DIV/0! | F41: =_xlfn.FORECAST.LINEAR(E41,$A$6:$A$11,$B$6:$B$11) -> #DIV/0! | G41: =ABS(F41-A41) -> #DIV/0!
A42: 0.11 | B42: =_xlfn.FORECAST.LINEAR(A42,$B$6:$B$11,$A$6:$A$11) -> #DIV/0! | C42: =_xlfn.FORECAST.LINEAR(B42,$A$6:$A$11,$D$6:$D$11) -> #DIV/0! | D42: =ABS(C42-A42) -> #DIV/0! | E42: =_xlfn.FORECAST.LINEAR(A42,$D$6:$D$11,$A$6:$A$11) -> #DIV/0! | F42: =_xlfn.FORECAST.LINEAR(E42,$A$6:$A$11,$B$6:$B$11) -> #DIV/0! | G42: =ABS(F42-A42) -> #DIV/0!
