Workbook

Sheet F.3.4 Steel Tube
B1: University Name | K1: =IF(C1="","BLANK","EQ") -> BLANK | M1: 2027 | N1: FSAE Structural Equivalency Spreadsheet (SES) | Z1: Steel Tube | AA1: 1.1 | AB1: SES Bug Reporting | AE1: Do not delete any tabs aside from extra F.4.2 Composite. | CX1: F.3.2.1 | CY1: F.3.4.1 | DI1: FBHS: Some examples and explanations for configurations A, B, and C. | EF1: SIS Examples | EN1: SIS with Rear FHB (or Forward MHB) | EU1: MHBS examples and explanations. | FJ1: Using Shoulder Harness Bar/Braces | FS1: Head Restraint Protection
B2: Team Name | K2: =IF(C2="","BLANK","EQ") -> BLANK | AB2: 1.1 | AE2: Guidance images may be deleted. | CX2: A round tube which is both the Minimum Diameter and the Minimum Wall Thickness may not meet
B3: Competitions | C3: May - IC | E3: June - EV | G3: Other - Edit | I3: Other - Edit | K3: EQ | M3: There are two versions of the 2027 SES: Steel Tube and Monocoque/Hybrid/Aluminum. | AB3: Welded / Bolted Activation | CX3: the Moment of Inertia and Cross Sectional Area Requirements.
B4: Car Numbers | K4: =IF(AND(NOT(ISNUMBER(C4)),NOT(ISNUMBER(G4)),NOT(ISNUMBER(E4)),NOT(ISNUMBER(I4))),"BLANK","EQ") -> BLANK | M4: Aluminum equivalance may be used in the Steel Tube SES for Anti-Intrusion, EV Rear Impact, or Tractive Battery Containers and Mounting. | AE4: Show dimensions in images, preferably not drawn on. | CX4: A square tube which is both the Minimum Width and the Minimum Wall Thickness always meets
B5: Team Contact(s) | K5: =IF(C5="","BLANK","EQ") -> BLANK | M5: Steel can be used for any part of the frame in the Monocoque/Hybrid/Aluminum SES. | AE5: Do not enter fractions or your sheet will be permanently broken | CX5: the Moment of Inertia and Cross Sectional Area Requirements.
B6: Email Address(es) | K6: =IF(C6="","BLANK","EQ") -> BLANK | M6: F.3.4.2 - Any and all steel grades are assigned the same material properties. No material properties for different steel grades may be used in the SES. | AE6: Use the same units as the SES, or show conversions, don't make us do math.
A7: Faculty Advisor | C7: Email Address | E7: Chassis Rules | G7: Powertrain | K7: EQ | CX7: The examples to the right cover the tube location requirements for the FBHS, SIS, and MHBS. There are many solutions not shown that can meet the documentation, triangulation, and bracing requirements. The examples to the left need to be replaced with your own CAD. Images should be clear, undistorted, moderate filesize. Each SES file 25MB max.
E8: Select Drop Down | G8: Select Drop Down | K8: =IF(OR(E8="Other Equivalence",G8="EV - Other Equivalence"),"REJECT", IF(OR(A8="",C8="",G8="Select Drop Down",E8="Select Drop Down"),"BLANK","EQ")) -> BLANK | M8: YouTube: 2019 SES Instructional Guide | R8: YouTube: 2020 ESF Document Training | V8: F.2.3 | W8: FEA is not accepted for any SES equivalency. | AE8: Grinding welds flush is prohibited, especially in structures regulated by rules.
F9: =IF(E8="Other Equivalence","FILL OUT THE MONOCOQUE/HYBRID/ALUMINUM SES.",IF(G8="EV - Other Equivalence","COMPOSITE BATTERY CONTAINERS REQUIRE COMPOSITE TESTING + MONOCOQUE SES","")) | K9: =IF(K8="REJECT",K8,"") | N9: Only cells of this color can be edited. Enter all values as positive numerals. | AU9: Front 3/4 3D CAD with color coded tube sizes required. | BD9: Rear 3/4 3D CAD with color coded tube sizes required.
A10: Overall | D10: Ready to submit for review? | J10: =IF(OR(A18="EQ",A18="CHECK"),"YES","NO") -> NO | M10: Drop down options can be identified by the heavy border. Delete will clear the entry. | AE10: We want to reward teams with a good Tech Number who: | BW10: Top and bottom views required for 30 degree bend check.
M11: Each entry, each category, each tab, and the entire sheet are coded as one of the following: | V11: BLANK | W11: EQ | X11: CHECK | Y11: REJECT | Z11: N/A | AE11: Submit good-quality documentation of rules-legal designs | AT11: Use different colors for square and round. | BE11: Use different colors for square and round.
B12: F.3.4 Steel Tube | C12: =IF(OR(COUNTIF(K1:K8,"BLANK"),COUNTIF(J56:EA57,"BLANK")),"BLANK", IF(OR(COUNTIF(K1:K9,"REJECT"),COUNTIF(J56:EA57,"REJECT")),"REJECT", IF(COUNTIF(J56:EA57,"CHECK"),"CHECK","EQ"))) -> BLANK | D12: BLUE: NO. BLANK ENTRY. INCOMPLETE. CHECK ALL TABS. | M12: The status of some cells depends on entries in other cells. | AE12: Work with the document reviewers quickly to resolve any issues with their submission
B13: F.10.1-4 Module&Contain | C13: =BS148 -> BLANK | D13: This will not change until all required entries are filled out. Check all tabs. | AE13: Submit documents early | AT13: Include a legend that shows each color and size. | BE13: Include a legend that shows each color and size. | BW13: Multiple or detail images may be used anywhere in the SES.
B14: F.10.5 Batt Attach | C14: =BS150 -> BLANK | D14: Incomplete submissions will incur a penalty. | M14: SELECT YOUR UNITS. The entire SES will be completed in either mm or Inch. Inch tubing can be entered in mm, and vice versa. | AE14: SES sets the IC Order. After Battery Video and ESF, SES was worth up to 25 places in EV 2026. | CX14: The row numbers are for reference only.
B15: F.8 Front Protection | C15: =BS152 -> BLANK | D15: RED ORANGE: NO. GROUNDS FOR REJECTION. CHECK ALL TABS. | M15: Keep a copy of the rules open to reference rule numbers directly while filling out the SES. | V15: How To Interpret Rules | AU15: Fuel tank or HV systems must be shown in orange. | BD15: Fuel tank or HV systems must be shown in orange. | CX15: Designating the FBHS as A,B, or C needed to check rule | DD15: F.6.2.3.ab
B16: F.3.4.3 Welded Inserts | C16: =BS154 -> BLANK | D16: The SES will permanently REJECT for removing any tab. Fill out a fresh copy. | M16: Fill in all | N16: BLANK | O16: sections on ALL TABS. Start with any drop downs in the top left corner of each tab. | AE16: You have up to 48 hours to resubmit before your Tech Number increases. | CX16: The other column letters are for reference only.
B17: F.5.12 Bolted Members | C17: =BS156 -> BLANK | D17: Locate all violations and bring the design into compliance before submitting. | M17: Replace example images with your own clear, undistorted CAD, showing all required dimensions in a moderate filesize. Each SES file 40Mb max. | AE17: Make sure every item is fixed.
A18: =IF(SUMPRODUCT(--ISERROR(C12:C17))>0,"REJECT", IF(COUNTIF(C12:C17,"BLANK"),"BLANK", IF(COUNTIF(C12:C17,"REJECT"),"REJECT", IF(COUNTIF(C12:C17,"CHECK"),"CHECK","EQ")))) -> BLANK | D18: Grounds for rejection could be considered incomplete and incur a penalty. | M18: ADDITIONAL GUIDANCE IMAGES ARE ON THE RIGHT SIDE OF DIFFERENT SHEETS | AE18: Comment with a description of every fix, and where to find the information in the SES. | CX18: Using this 7-color palette will accommodate color blind students or reviewers:
D19: SKY: YES. RULES EQUIVALENCE. | AE19: If it will take more than 48 hours to do additional testing, make a plan with your reviewer. | CX19: https://www.extensis.com/blog/how-to-design-for-color-blindness
D20: Document is ready for review. Double check triangulation. | L20: F.2.2.1 | M20: Current year SES forms must be completed and submitted by all teams no later than the date specified in the Action Deadlines on the specific event website. | CX20: In the examples to the right:
D21: Sheet protection must still be active when submitted, or the SES will be rejected. | L21: PS.3.2.1 | M21: Submission of late, blank, incomplete, or previous car's SES will incur a competition point penalty. | AE21: We think it benefits you and our reviewers to submit and get approved earlier. | CX21: THE SKY BLUE LINE is the upper tube
D22: YELLOW: YES. CHECK ADDITIONAL EQUIVALENCIES. | L22: PS.3.1.3 | M22: Please respond quickly and thoroughly to requests for revisions or clarifications. Response time influences Tech Inspection order. New review: Clock starts. Submit: Clock stops. | AE22: Submitting at the deadline increases the time to get a first review by several weeks. | CX22: THE YELLOW LINE is the lower tube
D23: Some entries require additional tubes or documentation. | M23: Please describe all changes made and their location in the SES for each re-submission. Make sure every entry is shown in an image. | CX23: BLACK LINES are additional related tubes
D24: Once these are added, document is ready for review. | M24: Resubmission after approval for engineering changes does not incur a clock penalty. The SES needs to match the car that comes to competition. | AE24: There is no penalty for resubmitting after approval. | CX24: RED ORANGE AREAS highlight design aspects that do not meet the rules
A25: mm | I25: Units | L25: IN.6.1 | M25: Bring an ELECTRONIC copy of the approved SES to Tech Inspection. It is your responsibility to bring a functioning, charged tablet or laptop. Bring backups. DO NOT PRINT. | AE25: Especially for small changes like fastener sizes. | CX25: White dotted lines | CZ25: represent potential design changes to an orange area to allow it to pass.
L26: IN.1.2.2 | M26: Approval of an SES does not guarantee passing Tech Inspection. The final decision about all designs will be made at Tech Inspection. | AE26: We need the document to match the car in Tech Inspection.
A27: Use the space below to list changes between uploads, rules inquiries, and any other information. | CX27: ACRONYMS
CX29: AI | CY29: Anti Intrusion Plate
CX30: IA | CY30: Impact Attenuator
CX31: IC | CY31: Internal Combustion
CX32: EV | CY32: Electric Vehicle
CX33: EQ | CY33: Rules Equivalence Achieved
AS34: Harness tabs cannot rub on harness material. | CX34: FB | CY34: Front Bulkhead
CX35: FBHS | CY35: Front Bulkhead Support
AS36: Use a thicker tab to keep the edge away. | CX36: FH | CY36: Front Roll Hoop
CX37: FHB | CY37: Front Hoop Brace
AS38: Harness tab location, dimensions, shear area, | CX38: HRP | CY38: Head Restraint Protection
K39: Front Hoop CAD with dimensions required. | U39: FBHS, FHB CAD with dimensions required. | AE39: SIS CAD with dimensions required. | AY39: MH + SH CAD with dimensions required. | BI39: MHB, MHBS CAD with dimensions required. | BS39: Clearance CAD with dimensions required. | CC39: HV Protection CAD with dimensions. | CM39: Rear Impact CAD with dimensions required. | CX39: HV | CY39: High Voltage
AS40: tabs in plane with belts. | CX40: MH | CY40: Main Roll Hoop
K41: See image F.5.9.6 for steering wheel. | U41: Highlight/trace/color code required tubes. | AE41: Highlight/trace/color code required tubes. | BI41: Highlight/trace/color code required tubes. | BS41: Helmet and T.2.8.4 Head Restraint. | CC41: Air gap driver to Tractive Battery assembly. | CX41: MHB | CY41: Main Hoop Brace
...

Sheet F.10.1-4 Modules And Container
A1: Match composite testing tabs and material list names. Properties auto-populate. No need to use "F.4.3 Composite" in the name. | E1: =IF($A$25="mm","Note: Forces are given in Pa, not Mpa or Gpa.","Note: Forces are given in psi, not ksi.") -> Note: Forces are given in Pa, not Mpa or Gpa.
E2: Material | G2: =IF($A$25="mm","E (Pa)","E (psi)") -> E (Pa) | I2: =IF($A$25="mm","S_Ultimate (Pa)","S_Ultimate (psi)") -> S_Ultimate (Pa) | K2: =IF($A$25="mm","Shear (Pa)","Shear (psi)") -> Shear (Pa) | L2: =_xlfn.CONCAT("S_Yield ",IF($A$25="mm","(Pa)","(psi)")) -> S_Yield (Pa)
E3: Steel Unwelded | G3: =IF($A$25="mm",200*10^9,29*10^6) -> 200000000000 | I3: =IF($A$25="mm",365*10^6,52.9*10^3) -> 365000000 | K3: =I3*0.577 -> 2.10605e+08 | L3: =IF($A$25="mm",305*10^6,44.2*10^3) -> 305000000
E4: Steel Welded | G4: =IF($A$25="mm",200*10^9,29*10^6) -> 200000000000 | I4: =IF($A$25="mm",300*10^6,43.5*10^3) -> 300000000 | K4: =I4*0.577 -> 173100000 | L4: =(L3/I3)*I4 -> 2.5068493e+08
E5: 6061-T6 Unwelded | G5: =IF($A$25="mm",69*10^9,10*10^6) -> 69000000000 | I5: =IF($A$25="mm",290*10^6,42.1*10^3) -> 290000000 | K5: =I5*0.577 -> 167330000 | L5: =IF($A$25="mm",240*10^6,34.8*10^3) -> 240000000
E6: 6061-T6 Welded | G6: =IF($A$25="mm",69*10^9,10*10^6) -> 69000000000 | I6: =IF($A$25="mm",175*10^6,25.4*10^3) -> 175000000 | K6: =I6*0.577 -> 1.00975e+08 | L6: =IF($A$25="mm",105*10^6,25.4*10^3) -> 105000000
E7: 5052-H32 Unwelded | G7: =IF($A$25="mm",70.3*10^9,10.2*10^6) -> 70300000000 | I7: =IF($A$25="mm",215*10^6,31.2*10^3) -> 215000000 | K7: =I7*0.577 -> 1.24055e+08 | L7: =IF($A$25="mm",160*10^6,23.2*10^3) -> 160000000
E8: 5052-H32 Welded | G8: =IF($A$25="mm",70.3*10^9,10.2*10^6) -> 70300000000 | I8: =IF($A$25="mm",170*10^6,24.6*10^3) -> 170000000 | K8: =I8*0.577 -> 98090000 | L8: =IF($A$25="mm",65*10^6,9.4*10^3) -> 65000000
A9: Doubled skin must repeat whole layup. Scroll up if Layup Used blank. | E9: Other Unwelded | K9: =I9*0.577 -> 0 | M9: Core | N9: Outer | O9: Inner | Q9: Show tractive battery in car, no holes toward driver. | AU9: Include data sheets for fasteners and material properties. | BC9: Include data sheets for fasteners and material properties.
E10: Other Welded | K10: =I10*0.577 -> 0 | M10: =IF($A$25="mm","mm","in") -> mm | N10: =IF($A$25="mm","mm","in") -> mm | O10: =IF($A$25="mm","mm","in") -> mm
D11: {=IF($E11="","",INDIRECT("'"&$E11&"'!$A$27"))} -> #REF! | E11: RENAME F.4.2 Composite | G11: {=IF($E11="","", IF($A$25="mm",INDIRECT("'"&$E11&"'!$AK$82"),INDIRECT("'"&$E11&"'!$AK$83")))} -> #REF! | I11: {=IF($E11="","", IF($A$25="mm",INDIRECT("'"&$E11&"'!$AK$85"),INDIRECT("'"&$E11&"'!$AK$86")))} -> #REF! | K11: {=IF($E11="","", IF($A$25="mm",INDIRECT("'"&$E11&"'!$AY$62"),INDIRECT("'"&$E11&"'!$AY$63")))} -> #REF! | M11: {=IF($E11="","", ROUND(IF($A$25="mm",1,1/25.4)*INDIRECT("'"&$E11&"'!$AK$61"),3))} -> #REF! | N11: {=IF($E11="","", ROUND(IF($A$25="mm",1,1/25.4)*INDIRECT("'"&$E11&"'!$AK$62"),3))} -> #REF! | O11: {=IF($E11="","", ROUND(IF($A$25="mm",1,1/25.4)*INDIRECT("'"&$E11&"'!$AK$63"),3))} -> #REF! | Q11: Show airflow paths from each segment to ambient or relief valve.
D12: {=IF($E12="","",INDIRECT("'"&$E12&"'!$A$27"))} | G12: {=IF($E12="","", IF($A$25="mm",INDIRECT("'"&$E12&"'!$AK$82"),INDIRECT("'"&$E12&"'!$AK$83")))} | I12: {=IF($E12="","", IF($A$25="mm",INDIRECT("'"&$E12&"'!$AK$85"),INDIRECT("'"&$E12&"'!$AK$86")))} | K12: {=IF($E12="","", IF($A$25="mm",INDIRECT("'"&$E12&"'!$AY$62"),INDIRECT("'"&$E12&"'!$AY$63")))} | M12: {=IF($E12="","", ROUND(IF($A$25="mm",1,1/25.4)*INDIRECT("'"&$E12&"'!$AK$61"),3))} | N12: {=IF($E12="","", ROUND(IF($A$25="mm",1,1/25.4)*INDIRECT("'"&$E12&"'!$AK$62"),3))} | O12: {=IF($E12="","", ROUND(IF($A$25="mm",1,1/25.4)*INDIRECT("'"&$E12&"'!$AK$63"),3))}
D13: {=IF($E13="","",INDIRECT("'"&$E13&"'!$A$27"))} | G13: {=IF($E13="","", IF($A$25="mm",INDIRECT("'"&$E13&"'!$AK$82"),INDIRECT("'"&$E13&"'!$AK$83")))} | I13: {=IF($E13="","", IF($A$25="mm",INDIRECT("'"&$E13&"'!$AK$85"),INDIRECT("'"&$E13&"'!$AK$86")))} | K13: {=IF($E13="","", IF($A$25="mm",INDIRECT("'"&$E13&"'!$AY$62"),INDIRECT("'"&$E13&"'!$AY$63")))} | M13: {=IF($E13="","", ROUND(IF($A$25="mm",1,1/25.4)*INDIRECT("'"&$E13&"'!$AK$61"),3))} | N13: {=IF($E13="","", ROUND(IF($A$25="mm",1,1/25.4)*INDIRECT("'"&$E13&"'!$AK$62"),3))} | O13: {=IF($E13="","", ROUND(IF($A$25="mm",1,1/25.4)*INDIRECT("'"&$E13&"'!$AK$63"),3))} | Q13: Show arrangement of modules in container.
D14: {=IF($E14="","",INDIRECT("'"&$E14&"'!$A$27"))} | G14: {=IF($E14="","", IF($A$25="mm",INDIRECT("'"&$E14&"'!$AK$82"),INDIRECT("'"&$E14&"'!$AK$83")))} | I14: {=IF($E14="","", IF($A$25="mm",INDIRECT("'"&$E14&"'!$AK$85"),INDIRECT("'"&$E14&"'!$AK$86")))} | K14: {=IF($E14="","", IF($A$25="mm",INDIRECT("'"&$E14&"'!$AY$62"),INDIRECT("'"&$E14&"'!$AY$63")))} | M14: {=IF($E14="","", ROUND(IF($A$25="mm",1,1/25.4)*INDIRECT("'"&$E14&"'!$AK$61"),3))} | N14: {=IF($E14="","", ROUND(IF($A$25="mm",1,1/25.4)*INDIRECT("'"&$E14&"'!$AK$62"),3))} | O14: {=IF($E14="","", ROUND(IF($A$25="mm",1,1/25.4)*INDIRECT("'"&$E14&"'!$AK$63"),3))}
D15: {=IF($E15="","",INDIRECT("'"&$E15&"'!$A$27"))} | G15: {=IF($E15="","", IF($A$25="mm",INDIRECT("'"&$E15&"'!$AK$82"),INDIRECT("'"&$E15&"'!$AK$83")))} | I15: {=IF($E15="","", IF($A$25="mm",INDIRECT("'"&$E15&"'!$AK$85"),INDIRECT("'"&$E15&"'!$AK$86")))} | K15: {=IF($E15="","", IF($A$25="mm",INDIRECT("'"&$E15&"'!$AY$62"),INDIRECT("'"&$E15&"'!$AY$63")))} | M15: {=IF($E15="","", ROUND(IF($A$25="mm",1,1/25.4)*INDIRECT("'"&$E15&"'!$AK$61"),3))} | N15: {=IF($E15="","", ROUND(IF($A$25="mm",1,1/25.4)*INDIRECT("'"&$E15&"'!$AK$62"),3))} | O15: {=IF($E15="","", ROUND(IF($A$25="mm",1,1/25.4)*INDIRECT("'"&$E15&"'!$AK$63"),3))}
A16: {=IF(ISREF(INDIRECT("'F.3.4-5 Tube Chassis"&"'!G8")),INDIRECT("'F.3.4-5 Tube Chassis"&"'!G8"),INDIRECT("'F.3.4 Steel Tube"&"'!G8"))} -> Select Drop Down | D16: {=IF($E16="","",INDIRECT("'"&$E16&"'!$A$27"))} | G16: {=IF($E16="","", IF($A$25="mm",INDIRECT("'"&$E16&"'!$AK$82"),INDIRECT("'"&$E16&"'!$AK$83")))} | I16: {=IF($E16="","", IF($A$25="mm",INDIRECT("'"&$E16&"'!$AK$85"),INDIRECT("'"&$E16&"'!$AK$86")))} | K16: {=IF($E16="","", IF($A$25="mm",INDIRECT("'"&$E16&"'!$AY$62"),INDIRECT("'"&$E16&"'!$AY$63")))} | M16: {=IF($E16="","", ROUND(IF($A$25="mm",1,1/25.4)*INDIRECT("'"&$E16&"'!$AK$61"),3))} | N16: {=IF($E16="","", ROUND(IF($A$25="mm",1,1/25.4)*INDIRECT("'"&$E16&"'!$AK$62"),3))} | O16: {=IF($E16="","", ROUND(IF($A$25="mm",1,1/25.4)*INDIRECT("'"&$E16&"'!$AK$63"),3))}
A17: =IF(A16="IC - Internal Combustion","N/A", IF(COUNTIF(U56:CV57,"BLANK"),"BLANK", IF(COUNTIF(U56:CV57,"REJECT"),"REJECT", IF(COUNTIF(U56:CV57,"CHECK"),"CHECK","EQ")))) -> BLANK | D17: {=IF($E17="","",INDIRECT("'"&$E17&"'!$A$27"))} | G17: {=IF($E17="","", IF($A$25="mm",INDIRECT("'"&$E17&"'!$AK$82"),INDIRECT("'"&$E17&"'!$AK$83")))} | I17: {=IF($E17="","", IF($A$25="mm",INDIRECT("'"&$E17&"'!$AK$85"),INDIRECT("'"&$E17&"'!$AK$86")))} | K17: {=IF($E17="","", IF($A$25="mm",INDIRECT("'"&$E17&"'!$AY$62"),INDIRECT("'"&$E17&"'!$AY$63")))} | M17: {=IF($E17="","", ROUND(IF($A$25="mm",1,1/25.4)*INDIRECT("'"&$E17&"'!$AK$61"),3))} | N17: {=IF($E17="","", ROUND(IF($A$25="mm",1,1/25.4)*INDIRECT("'"&$E17&"'!$AK$62"),3))} | O17: {=IF($E17="","", ROUND(IF($A$25="mm",1,1/25.4)*INDIRECT("'"&$E17&"'!$AK$63"),3))}
D18: {=IF($E18="","",INDIRECT("'"&$E18&"'!$A$27"))} | G18: {=IF($E18="","", IF($A$25="mm",INDIRECT("'"&$E18&"'!$AK$82"),INDIRECT("'"&$E18&"'!$AK$83")))} | I18: {=IF($E18="","", IF($A$25="mm",INDIRECT("'"&$E18&"'!$AK$85"),INDIRECT("'"&$E18&"'!$AK$86")))} | K18: {=IF($E18="","", IF($A$25="mm",INDIRECT("'"&$E18&"'!$AY$62"),INDIRECT("'"&$E18&"'!$AY$63")))} | M18: {=IF($E18="","", ROUND(IF($A$25="mm",1,1/25.4)*INDIRECT("'"&$E18&"'!$AK$61"),3))} | N18: {=IF($E18="","", ROUND(IF($A$25="mm",1,1/25.4)*INDIRECT("'"&$E18&"'!$AK$62"),3))} | O18: {=IF($E18="","", ROUND(IF($A$25="mm",1,1/25.4)*INDIRECT("'"&$E18&"'!$AK$63"),3))}
D19: {=IF($E19="","",INDIRECT("'"&$E19&"'!$A$27"))} | G19: {=IF($E19="","", IF($A$25="mm",INDIRECT("'"&$E19&"'!$AK$82"),INDIRECT("'"&$E19&"'!$AK$83")))} | I19: {=IF($E19="","", IF($A$25="mm",INDIRECT("'"&$E19&"'!$AK$85"),INDIRECT("'"&$E19&"'!$AK$86")))} | K19: {=IF($E19="","", IF($A$25="mm",INDIRECT("'"&$E19&"'!$AY$62"),INDIRECT("'"&$E19&"'!$AY$63")))} | M19: {=IF($E19="","", ROUND(IF($A$25="mm",1,1/25.4)*INDIRECT("'"&$E19&"'!$AK$61"),3))} | N19: {=IF($E19="","", ROUND(IF($A$25="mm",1,1/25.4)*INDIRECT("'"&$E19&"'!$AK$62"),3))} | O19: {=IF($E19="","", ROUND(IF($A$25="mm",1,1/25.4)*INDIRECT("'"&$E19&"'!$AK$63"),3))}
D20: {=IF($E20="","",INDIRECT("'"&$E20&"'!$A$27"))} | G20: {=IF($E20="","", IF($A$25="mm",INDIRECT("'"&$E20&"'!$AK$82"),INDIRECT("'"&$E20&"'!$AK$83")))} | I20: {=IF($E20="","", IF($A$25="mm",INDIRECT("'"&$E20&"'!$AK$85"),INDIRECT("'"&$E20&"'!$AK$86")))} | K20: {=IF($E20="","", IF($A$25="mm",INDIRECT("'"&$E20&"'!$AY$62"),INDIRECT("'"&$E20&"'!$AY$63")))} | M20: {=IF($E20="","", ROUND(IF($A$25="mm",1,1/25.4)*INDIRECT("'"&$E20&"'!$AK$61"),3))} | N20: {=IF($E20="","", ROUND(IF($A$25="mm",1,1/25.4)*INDIRECT("'"&$E20&"'!$AK$62"),3))} | O20: {=IF($E20="","", ROUND(IF($A$25="mm",1,1/25.4)*INDIRECT("'"&$E20&"'!$AK$63"),3))}
D21: {=IF($E21="","",INDIRECT("'"&$E21&"'!$A$27"))} | G21: {=IF($E21="","", IF($A$25="mm",INDIRECT("'"&$E21&"'!$AK$82"),INDIRECT("'"&$E21&"'!$AK$83")))} | I21: {=IF($E21="","", IF($A$25="mm",INDIRECT("'"&$E21&"'!$AK$85"),INDIRECT("'"&$E21&"'!$AK$86")))} | K21: {=IF($E21="","", IF($A$25="mm",INDIRECT("'"&$E21&"'!$AY$62"),INDIRECT("'"&$E21&"'!$AY$63")))} | M21: {=IF($E21="","", ROUND(IF($A$25="mm",1,1/25.4)*INDIRECT("'"&$E21&"'!$AK$61"),3))} | N21: {=IF($E21="","", ROUND(IF($A$25="mm",1,1/25.4)*INDIRECT("'"&$E21&"'!$AK$62"),3))} | O21: {=IF($E21="","", ROUND(IF($A$25="mm",1,1/25.4)*INDIRECT("'"&$E21&"'!$AK$63"),3))}
A25: {=IF(ISREF(INDIRECT("'F.3.4-5 Tube Chassis"&"'!$A$25")),INDIRECT("'F.3.4-5 Tube Chassis"&"'!$A$25"),INDIRECT("'F.3.4 Steel Tube"&"'!$A$25"))} -> mm
A27: Design Suggestions To Resolve A Red Car Situation Quickly | J27: F.2.3 | K27: FEA is not accepted anywhere in the SES or Tech Inspection.
A29: Include a cell temperature display and other vital battery readings | K29: The SES is asking about the structure of a single module.
A30: on an easily visible Low Voltage display.
A31: Include diagnostic cable connections. | K31: • removed from the tractive battery container
A32: Design the charger to connect while the Tractive Battery is in the car. | K32: • aligned lat/long/vert as it is in the car
A33: Design the Tractive Battery to be easily removable while wearing PPE. | K33: • don't worry about small differences in angle
A34: Include a mid-pack HVD. | K34: The SES will create a test load
K35: mass of one module * acceleration * number of modules in a row.
A36: Design Suggestions To Pass The Rain Test | K36: For example, a tractive battery that is 4 modules wide and 2 modules
K37: mass * acceleration force multiplied by 4x laterally, and 2x longitudinally
A38: Where does the water go? | K38: Module cross sections are taken with all cells, wiring, cooling, etc. removed. | BM38: Module cross section, Top View.
A39: Keep as much moisture away from and out of the powertrain as possible. | K39: And furthermore, treating hole patterns as one large opening. | Y39: 3/4 view of single module | AI39: 3/4 view of single module, structure only | AS39: Module cross section, Front View. | BC39: Module cross section, Side View. | BS39: Module cross section and attachment CAD. | CC39: Show all wall attachments / weld paths. | CM39: Show all wall attachments / weld paths.
A40: Deflect spray during the rain test or off the wheels. | K40: The front view cross section carries longitudinal load. | BM40: Select smallest column, show A and MOI.
A41: Where does water fall off the rear wing? | K41: The side view cross section carries lateral load. | AS41: Select smallest column, show A and MOI. | BC41: Select smallest column, show A and MOI. | BW41: Show all dimensions entered. | CC41: All walls must attach to floor. | CM41: All walls must attach to floor.
A42: Provide a path for water to drain out of the bodywork. | K42: The top view cross section carries vertical load.
A43: Avoid flat, level surfaces where water can pool. | K43: From statics class:
A44: Use downturned drip edges out past openings for connectors. | K44: A column is continuous in area and continuous along its normal.
A45: Do not use upward facing connectors, indicators, | K45: If there are multiple separate cross sectional areas, select only the smallest for A and MOI.
...

Sheet F.10.3.5 Module Test
L1: Paste in logged data from test below: | AC1: Paste in logged data from test below: | AT1: Paste in logged data from test below: | BK1: Paste in logged data from test below:
L2: Use mm and N, paste values only. | AC2: Use mm and N, paste values only. | AT2: Use mm and N, paste values only. | BK2: Use mm and N, paste values only.
L3: It is acceptable to resample the data at a lower | AC3: It is acceptable to resample the data at a lower | AT3: It is acceptable to resample the data at a lower | BK3: It is acceptable to resample the data at a lower
L4: frequency to reduce the number of datapoints. | AC4: frequency to reduce the number of datapoints. | AT4: frequency to reduce the number of datapoints. | BK4: frequency to reduce the number of datapoints.
L5: Repeat the energy calculation in column three. | AC5: Repeat the energy calculation in column three. | AT5: Repeat the energy calculation in column three. | BK5: Repeat the energy calculation in column three.
L6: The graph should automatically generate. | AC6: The graph should automatically generate. | AT6: The graph should automatically generate. | BK6: The graph should automatically generate.
B8: Required: Test setup images, measurements. | L8: X Direction | N8: Y Direction | P8: Z Direction | S8: Required: Test setup images, measurements. | AC8: ROOM TEMP | AF8: 60C | AJ8: Required: Test setup images, measurements. | AT8: ROOM TEMP | AW8: 60C | BA8: Required: Test setup images, measurements. | BK8: ROOM TEMP | BN8: 60C
L9: MAX | M9: {=INDEX(L$14:L$1048576,MATCH(TRUE,M$14:M$1048576=M10,0))} -> 0 | N9: MAX | O9: {=INDEX(N$14:N$1048576,MATCH(TRUE,O$14:O$1048576=O10,0))} -> 0 | P9: MAX | Q9: {=INDEX(P$14:P$1048576,MATCH(TRUE,Q$14:Q$1048576=Q10,0))} -> 0 | AC9: MAX | AD9: {=INDEX(AC$14:AC$1048576,MATCH(TRUE,AD$14:AD$1048576=AD10,0))} -> 0 | AE9: LINEAR | AF9: MAX | AG9: {=INDEX(AF$14:AF$1048576,MATCH(TRUE,AG$14:AG$1048576=AG10,0))} -> 0 | AH9: LINEAR | AT9: MAX | AU9: {=INDEX(AT$14:AT$1048576,MATCH(TRUE,AU$14:AU$1048576=AU10,0))} -> 0 | AV9: LINEAR | AW9: MAX | AX9: {=INDEX(AW$14:AW$1048576,MATCH(TRUE,AX$14:AX$1048576=AX10,0))} -> 0 | AY9: LINEAR | BK9: MAX | BL9: {=INDEX(BK$14:BK$1048576,MATCH(TRUE,BL$14:BL$1048576=BL10,0))} -> 0 | BM9: LINEAR | BN9: MAX | BO9: {=INDEX(BN$14:BN$1048576,MATCH(TRUE,BO$14:BO$1048576=BO10,0))} -> 0 | BP9: LINEAR
B10: All test samples must be presented at Technical Inspection. | L10: =MAX(L14:L1048576) -> 0 | M10: =MAX(M14:M1048576) -> 0 | N10: =MAX(N14:N1048576) -> 0 | O10: =MAX(O14:O1048576) -> 0 | P10: =MAX(P14:P1048576) -> 0 | Q10: =MAX(Q14:Q1048576) -> 0 | S10: All test samples must be presented at Technical Inspection. | AC10: =MAX(AC14:AC1048576) -> 0 | AD10: =MAX(AD14:AD1048576) -> 0 | AE10: =(Y53-Y52)/(U53-U52) -> #DIV/0! | AF10: =MAX(AF14:AF1048576) -> 0 | AG10: =MAX(AG14:AG1048576) -> 0 | AH10: =(Y66-Y65)/(U66-U65) -> #DIV/0! | AJ10: All test samples must be presented at Technical Inspection. | AT10: =MAX(AT14:AT1048576) -> 0 | AU10: =MAX(AU14:AU1048576) -> 0 | AV10: =(AP53-AP52)/(AL53-AL52) -> #DIV/0! | AW10: =MAX(AW14:AW1048576) -> 0 | AX10: =MAX(AX14:AX1048576) -> 0 | AY10: =(AP66-AP65)/(AL66-AL65) -> #DIV/0! | BA10: All test samples must be presented at Technical Inspection. | BK10: =MAX(BK14:BK1048576) -> 0 | BL10: =MAX(BL14:BL1048576) -> 0 | BM10: =(BG53-BG52)/(BC53-BC52) -> #DIV/0! | BN10: =MAX(BN14:BN1048576) -> 0 | BO10: =MAX(BO14:BO1048576) -> 0 | BP10: =(BG66-BG65)/(BC66-BC65) -> #DIV/0!
L11: mm | M11: N | N11: mm | O11: N | P11: mm | Q11: N | AC11: mm | AD11: N | AE11: =Y53-AE10*U53 -> #DIV/0! | AF11: mm | AG11: N | AH11: =Y66-AH10*U66 -> #DIV/0! | AT11: mm | AU11: N | AV11: =AP53-AV10*AL53 -> #DIV/0! | AW11: mm | AX11: N | AY11: =AP66-AY10*AL66 -> #DIV/0! | BK11: mm | BL11: N | BM11: =BG53-BM10*BC53 -> #DIV/0! | BN11: mm | BO11: N | BP11: =BG66-BP10*BC66 -> #DIV/0!
L12: Disp. (d) | M12: Force (P) | N12: Disp. (d) | O12: Force (P) | P12: Disp. (d) | Q12: Force (P) | AC12: Disp. (d) | AD12: Force (P) | AE12: Modulus | AF12: Disp. (d) | AG12: Force (P) | AH12: Modulus | AT12: Disp. (d) | AU12: Force (P) | AV12: Modulus | AW12: Disp. (d) | AX12: Force (P) | AY12: Modulus | BK12: Disp. (d) | BL12: Force (P) | BM12: Modulus | BN12: Disp. (d) | BO12: Force (P) | BP12: Modulus
L13: 0 | M13: 0 | N13: 0 | O13: 0 | P13: 0 | Q13: 0 | AC13: 0 | AD13: 0 | AE13: 0 | AF13: 0 | AG13: 0 | AH13: 0 | AT13: 0 | AU13: 0 | AV13: 0 | AW13: 0 | AX13: 0 | AY13: 0 | BK13: 0 | BL13: 0 | BM13: 0 | BN13: 0 | BO13: 0 | BP13: 0
B14: Additional images may be added below. | L14: 0 | M14: 0 | N14: 0 | O14: 0 | P14: 0 | Q14: 0 | S14: Additional images may be added below. | AC14: 0 | AD14: 0 | AE14: =IF(AE$10*AC14+AE$11<(ROUNDUP(AD$10/100,0)*100+999),MAX(0,AE$10*AC14+AE$11),NA()) -> #DIV/0! | AF14: 0 | AG14: 0 | AH14: =IF(AH$10*AF14+AH$11<(ROUNDUP(AG$10/100,0)*100+999),MAX(0,AH$10*AF14+AH$11),NA()) -> #DIV/0! | AJ14: Additional images may be added below. | AT14: 0 | AU14: 0 | AV14: =IF(AV$10*AT14+AV$11<(ROUNDUP(AU$10/100,0)*100+999),MAX(0,AV$10*AT14+AV$11),NA()) -> #DIV/0! | AW14: 0 | AX14: 0 | AY14: =IF(AY$10*AW14+AY$11<(ROUNDUP(AX$10/100,0)*100+999),MAX(0,AY$10*AW14+AY$11),NA()) -> #DIV/0! | BA14: Additional images may be added below. | BK14: 0 | BL14: 0 | BM14: =IF(BM$10*BK14+BM$11<(ROUNDUP(BL$10/100,0)*100+999),MAX(0,BM$10*BK14+BM$11),NA()) -> #DIV/0! | BN14: 0 | BO14: 0 | BP14: =IF(BP$10*BN14+BP$11<(ROUNDUP(BO$10/100,0)*100+999),MAX(0,BP$10*BN14+BP$11),NA()) -> #DIV/0!
AE15: =IF(AE$10*AC15+AE$11<(ROUNDUP(AD$10/100,0)*100+999),MAX(0,AE$10*AC15+AE$11),NA()) -> #DIV/0! | AH15: =IF(AH$10*AF15+AH$11<(ROUNDUP(AG$10/100,0)*100+999),MAX(0,AH$10*AF15+AH$11),NA()) -> #DIV/0! | AV15: =IF(AV$10*AT15+AV$11<(ROUNDUP(AU$10/100,0)*100+999),MAX(0,AV$10*AT15+AV$11),NA()) -> #DIV/0! | AY15: =IF(AY$10*AW15+AY$11<(ROUNDUP(AX$10/100,0)*100+999),MAX(0,AY$10*AW15+AY$11),NA()) -> #DIV/0! | BM15: =IF(BM$10*BK15+BM$11<(ROUNDUP(BL$10/100,0)*100+999),MAX(0,BM$10*BK15+BM$11),NA()) -> #DIV/0! | BP15: =IF(BP$10*BN15+BP$11<(ROUNDUP(BO$10/100,0)*100+999),MAX(0,BP$10*BN15+BP$11),NA()) -> #DIV/0!
AE16: =IF(AE$10*AC16+AE$11<(ROUNDUP(AD$10/100,0)*100+999),MAX(0,AE$10*AC16+AE$11),NA()) -> #DIV/0! | AH16: =IF(AH$10*AF16+AH$11<(ROUNDUP(AG$10/100,0)*100+999),MAX(0,AH$10*AF16+AH$11),NA()) -> #DIV/0! | AV16: =IF(AV$10*AT16+AV$11<(ROUNDUP(AU$10/100,0)*100+999),MAX(0,AV$10*AT16+AV$11),NA()) -> #DIV/0! | AY16: =IF(AY$10*AW16+AY$11<(ROUNDUP(AX$10/100,0)*100+999),MAX(0,AY$10*AW16+AY$11),NA()) -> #DIV/0! | BM16: =IF(BM$10*BK16+BM$11<(ROUNDUP(BL$10/100,0)*100+999),MAX(0,BM$10*BK16+BM$11),NA()) -> #DIV/0! | BP16: =IF(BP$10*BN16+BP$11<(ROUNDUP(BO$10/100,0)*100+999),MAX(0,BP$10*BN16+BP$11),NA()) -> #DIV/0!
AE17: =IF(AE$10*AC17+AE$11<(ROUNDUP(AD$10/100,0)*100+999),MAX(0,AE$10*AC17+AE$11),NA()) -> #DIV/0! | AH17: =IF(AH$10*AF17+AH$11<(ROUNDUP(AG$10/100,0)*100+999),MAX(0,AH$10*AF17+AH$11),NA()) -> #DIV/0! | AV17: =IF(AV$10*AT17+AV$11<(ROUNDUP(AU$10/100,0)*100+999),MAX(0,AV$10*AT17+AV$11),NA()) -> #DIV/0! | AY17: =IF(AY$10*AW17+AY$11<(ROUNDUP(AX$10/100,0)*100+999),MAX(0,AY$10*AW17+AY$11),NA()) -> #DIV/0! | BM17: =IF(BM$10*BK17+BM$11<(ROUNDUP(BL$10/100,0)*100+999),MAX(0,BM$10*BK17+BM$11),NA()) -> #DIV/0! | BP17: =IF(BP$10*BN17+BP$11<(ROUNDUP(BO$10/100,0)*100+999),MAX(0,BP$10*BN17+BP$11),NA()) -> #DIV/0!
AE18: =IF(AE$10*AC18+AE$11<(ROUNDUP(AD$10/100,0)*100+999),MAX(0,AE$10*AC18+AE$11),NA()) -> #DIV/0! | AH18: =IF(AH$10*AF18+AH$11<(ROUNDUP(AG$10/100,0)*100+999),MAX(0,AH$10*AF18+AH$11),NA()) -> #DIV/0! | AV18: =IF(AV$10*AT18+AV$11<(ROUNDUP(AU$10/100,0)*100+999),MAX(0,AV$10*AT18+AV$11),NA()) -> #DIV/0! | AY18: =IF(AY$10*AW18+AY$11<(ROUNDUP(AX$10/100,0)*100+999),MAX(0,AY$10*AW18+AY$11),NA()) -> #DIV/0! | BM18: =IF(BM$10*BK18+BM$11<(ROUNDUP(BL$10/100,0)*100+999),MAX(0,BM$10*BK18+BM$11),NA()) -> #DIV/0! | BP18: =IF(BP$10*BN18+BP$11<(ROUNDUP(BO$10/100,0)*100+999),MAX(0,BP$10*BN18+BP$11),NA()) -> #DIV/0!
AE19: =IF(AE$10*AC19+AE$11<(ROUNDUP(AD$10/100,0)*100+999),MAX(0,AE$10*AC19+AE$11),NA()) -> #DIV/0! | AH19: =IF(AH$10*AF19+AH$11<(ROUNDUP(AG$10/100,0)*100+999),MAX(0,AH$10*AF19+AH$11),NA()) -> #DIV/0! | AV19: =IF(AV$10*AT19+AV$11<(ROUNDUP(AU$10/100,0)*100+999),MAX(0,AV$10*AT19+AV$11),NA()) -> #DIV/0! | AY19: =IF(AY$10*AW19+AY$11<(ROUNDUP(AX$10/100,0)*100+999),MAX(0,AY$10*AW19+AY$11),NA()) -> #DIV/0! | BM19: =IF(BM$10*BK19+BM$11<(ROUNDUP(BL$10/100,0)*100+999),MAX(0,BM$10*BK19+BM$11),NA()) -> #DIV/0! | BP19: =IF(BP$10*BN19+BP$11<(ROUNDUP(BO$10/100,0)*100+999),MAX(0,BP$10*BN19+BP$11),NA()) -> #DIV/0!
AE20: =IF(AE$10*AC20+AE$11<(ROUNDUP(AD$10/100,0)*100+999),MAX(0,AE$10*AC20+AE$11),NA()) -> #DIV/0! | AH20: =IF(AH$10*AF20+AH$11<(ROUNDUP(AG$10/100,0)*100+999),MAX(0,AH$10*AF20+AH$11),NA()) -> #DIV/0! | AV20: =IF(AV$10*AT20+AV$11<(ROUNDUP(AU$10/100,0)*100+999),MAX(0,AV$10*AT20+AV$11),NA()) -> #DIV/0! | AY20: =IF(AY$10*AW20+AY$11<(ROUNDUP(AX$10/100,0)*100+999),MAX(0,AY$10*AW20+AY$11),NA()) -> #DIV/0! | BM20: =IF(BM$10*BK20+BM$11<(ROUNDUP(BL$10/100,0)*100+999),MAX(0,BM$10*BK20+BM$11),NA()) -> #DIV/0! | BP20: =IF(BP$10*BN20+BP$11<(ROUNDUP(BO$10/100,0)*100+999),MAX(0,BP$10*BN20+BP$11),NA()) -> #DIV/0!
AE21: =IF(AE$10*AC21+AE$11<(ROUNDUP(AD$10/100,0)*100+999),MAX(0,AE$10*AC21+AE$11),NA()) -> #DIV/0! | AH21: =IF(AH$10*AF21+AH$11<(ROUNDUP(AG$10/100,0)*100+999),MAX(0,AH$10*AF21+AH$11),NA()) -> #DIV/0! | AV21: =IF(AV$10*AT21+AV$11<(ROUNDUP(AU$10/100,0)*100+999),MAX(0,AV$10*AT21+AV$11),NA()) -> #DIV/0! | AY21: =IF(AY$10*AW21+AY$11<(ROUNDUP(AX$10/100,0)*100+999),MAX(0,AY$10*AW21+AY$11),NA()) -> #DIV/0! | BM21: =IF(BM$10*BK21+BM$11<(ROUNDUP(BL$10/100,0)*100+999),MAX(0,BM$10*BK21+BM$11),NA()) -> #DIV/0! | BP21: =IF(BP$10*BN21+BP$11<(ROUNDUP(BO$10/100,0)*100+999),MAX(0,BP$10*BN21+BP$11),NA()) -> #DIV/0!
AE22: =IF(AE$10*AC22+AE$11<(ROUNDUP(AD$10/100,0)*100+999),MAX(0,AE$10*AC22+AE$11),NA()) -> #DIV/0! | AH22: =IF(AH$10*AF22+AH$11<(ROUNDUP(AG$10/100,0)*100+999),MAX(0,AH$10*AF22+AH$11),NA()) -> #DIV/0! | AV22: =IF(AV$10*AT22+AV$11<(ROUNDUP(AU$10/100,0)*100+999),MAX(0,AV$10*AT22+AV$11),NA()) -> #DIV/0! | AY22: =IF(AY$10*AW22+AY$11<(ROUNDUP(AX$10/100,0)*100+999),MAX(0,AY$10*AW22+AY$11),NA()) -> #DIV/0! | BM22: =IF(BM$10*BK22+BM$11<(ROUNDUP(BL$10/100,0)*100+999),MAX(0,BM$10*BK22+BM$11),NA()) -> #DIV/0! | BP22: =IF(BP$10*BN22+BP$11<(ROUNDUP(BO$10/100,0)*100+999),MAX(0,BP$10*BN22+BP$11),NA()) -> #DIV/0!
AE23: =IF(AE$10*AC23+AE$11<(ROUNDUP(AD$10/100,0)*100+999),MAX(0,AE$10*AC23+AE$11),NA()) -> #DIV/0! | AH23: =IF(AH$10*AF23+AH$11<(ROUNDUP(AG$10/100,0)*100+999),MAX(0,AH$10*AF23+AH$11),NA()) -> #DIV/0! | AV23: =IF(AV$10*AT23+AV$11<(ROUNDUP(AU$10/100,0)*100+999),MAX(0,AV$10*AT23+AV$11),NA()) -> #DIV/0! | AY23: =IF(AY$10*AW23+AY$11<(ROUNDUP(AX$10/100,0)*100+999),MAX(0,AY$10*AW23+AY$11),NA()) -> #DIV/0! | BM23: =IF(BM$10*BK23+BM$11<(ROUNDUP(BL$10/100,0)*100+999),MAX(0,BM$10*BK23+BM$11),NA()) -> #DIV/0! | BP23: =IF(BP$10*BN23+BP$11<(ROUNDUP(BO$10/100,0)*100+999),MAX(0,BP$10*BN23+BP$11),NA()) -> #DIV/0!
AE24: =IF(AE$10*AC24+AE$11<(ROUNDUP(AD$10/100,0)*100+999),MAX(0,AE$10*AC24+AE$11),NA()) -> #DIV/0! | AH24: =IF(AH$10*AF24+AH$11<(ROUNDUP(AG$10/100,0)*100+999),MAX(0,AH$10*AF24+AH$11),NA()) -> #DIV/0! | AV24: =IF(AV$10*AT24+AV$11<(ROUNDUP(AU$10/100,0)*100+999),MAX(0,AV$10*AT24+AV$11),NA()) -> #DIV/0! | AY24: =IF(AY$10*AW24+AY$11<(ROUNDUP(AX$10/100,0)*100+999),MAX(0,AY$10*AW24+AY$11),NA()) -> #DIV/0! | BM24: =IF(BM$10*BK24+BM$11<(ROUNDUP(BL$10/100,0)*100+999),MAX(0,BM$10*BK24+BM$11),NA()) -> #DIV/0! | BP24: =IF(BP$10*BN24+BP$11<(ROUNDUP(BO$10/100,0)*100+999),MAX(0,BP$10*BN24+BP$11),NA()) -> #DIV/0!
AE25: =IF(AE$10*AC25+AE$11<(ROUNDUP(AD$10/100,0)*100+999),MAX(0,AE$10*AC25+AE$11),NA()) -> #DIV/0! | AH25: =IF(AH$10*AF25+AH$11<(ROUNDUP(AG$10/100,0)*100+999),MAX(0,AH$10*AF25+AH$11),NA()) -> #DIV/0! | AV25: =IF(AV$10*AT25+AV$11<(ROUNDUP(AU$10/100,0)*100+999),MAX(0,AV$10*AT25+AV$11),NA()) -> #DIV/0! | AY25: =IF(AY$10*AW25+AY$11<(ROUNDUP(AX$10/100,0)*100+999),MAX(0,AY$10*AW25+AY$11),NA()) -> #DIV/0! | BM25: =IF(BM$10*BK25+BM$11<(ROUNDUP(BL$10/100,0)*100+999),MAX(0,BM$10*BK25+BM$11),NA()) -> #DIV/0! | BP25: =IF(BP$10*BN25+BP$11<(ROUNDUP(BO$10/100,0)*100+999),MAX(0,BP$10*BN25+BP$11),NA()) -> #DIV/0!
AE26: =IF(AE$10*AC26+AE$11<(ROUNDUP(AD$10/100,0)*100+999),MAX(0,AE$10*AC26+AE$11),NA()) -> #DIV/0! | AH26: =IF(AH$10*AF26+AH$11<(ROUNDUP(AG$10/100,0)*100+999),MAX(0,AH$10*AF26+AH$11),NA()) -> #DIV/0! | AV26: =IF(AV$10*AT26+AV$11<(ROUNDUP(AU$10/100,0)*100+999),MAX(0,AV$10*AT26+AV$11),NA()) -> #DIV/0! | AY26: =IF(AY$10*AW26+AY$11<(ROUNDUP(AX$10/100,0)*100+999),MAX(0,AY$10*AW26+AY$11),NA()) -> #DIV/0! | BM26: =IF(BM$10*BK26+BM$11<(ROUNDUP(BL$10/100,0)*100+999),MAX(0,BM$10*BK26+BM$11),NA()) -> #DIV/0! | BP26: =IF(BP$10*BN26+BP$11<(ROUNDUP(BO$10/100,0)*100+999),MAX(0,BP$10*BN26+BP$11),NA()) -> #DIV/0!
AE27: =IF(AE$10*AC27+AE$11<(ROUNDUP(AD$10/100,0)*100+999),MAX(0,AE$10*AC27+AE$11),NA()) -> #DIV/0! | AH27: =IF(AH$10*AF27+AH$11<(ROUNDUP(AG$10/100,0)*100+999),MAX(0,AH$10*AF27+AH$11),NA()) -> #DIV/0! | AV27: =IF(AV$10*AT27+AV$11<(ROUNDUP(AU$10/100,0)*100+999),MAX(0,AV$10*AT27+AV$11),NA()) -> #DIV/0! | AY27: =IF(AY$10*AW27+AY$11<(ROUNDUP(AX$10/100,0)*100+999),MAX(0,AY$10*AW27+AY$11),NA()) -> #DIV/0! | BM27: =IF(BM$10*BK27+BM$11<(ROUNDUP(BL$10/100,0)*100+999),MAX(0,BM$10*BK27+BM$11),NA()) -> #DIV/0! | BP27: =IF(BP$10*BN27+BP$11<(ROUNDUP(BO$10/100,0)*100+999),MAX(0,BP$10*BN27+BP$11),NA()) -> #DIV/0!
B28: Required: Load deflection curve. | S28: Required: Load deflection curve. | AE28: =IF(AE$10*AC28+AE$11<(ROUNDUP(AD$10/100,0)*100+999),MAX(0,AE$10*AC28+AE$11),NA()) -> #DIV/0! | AH28: =IF(AH$10*AF28+AH$11<(ROUNDUP(AG$10/100,0)*100+999),MAX(0,AH$10*AF28+AH$11),NA()) -> #DIV/0! | AJ28: Required: Load deflection curve. | AV28: =IF(AV$10*AT28+AV$11<(ROUNDUP(AU$10/100,0)*100+999),MAX(0,AV$10*AT28+AV$11),NA()) -> #DIV/0! | AY28: =IF(AY$10*AW28+AY$11<(ROUNDUP(AX$10/100,0)*100+999),MAX(0,AY$10*AW28+AY$11),NA()) -> #DIV/0! | BA28: Required: Load deflection curve. | BM28: =IF(BM$10*BK28+BM$11<(ROUNDUP(BL$10/100,0)*100+999),MAX(0,BM$10*BK28+BM$11),NA()) -> #DIV/0! | BP28: =IF(BP$10*BN28+BP$11<(ROUNDUP(BO$10/100,0)*100+999),MAX(0,BP$10*BN28+BP$11),NA()) -> #DIV/0!
AE29: =IF(AE$10*AC29+AE$11<(ROUNDUP(AD$10/100,0)*100+999),MAX(0,AE$10*AC29+AE$11),NA()) -> #DIV/0! | AH29: =IF(AH$10*AF29+AH$11<(ROUNDUP(AG$10/100,0)*100+999),MAX(0,AH$10*AF29+AH$11),NA()) -> #DIV/0! | AV29: =IF(AV$10*AT29+AV$11<(ROUNDUP(AU$10/100,0)*100+999),MAX(0,AV$10*AT29+AV$11),NA()) -> #DIV/0! | AY29: =IF(AY$10*AW29+AY$11<(ROUNDUP(AX$10/100,0)*100+999),MAX(0,AY$10*AW29+AY$11),NA()) -> #DIV/0! | BM29: =IF(BM$10*BK29+BM$11<(ROUNDUP(BL$10/100,0)*100+999),MAX(0,BM$10*BK29+BM$11),NA()) -> #DIV/0! | BP29: =IF(BP$10*BN29+BP$11<(ROUNDUP(BO$10/100,0)*100+999),MAX(0,BP$10*BN29+BP$11),NA()) -> #DIV/0!
AE30: =IF(AE$10*AC30+AE$11<(ROUNDUP(AD$10/100,0)*100+999),MAX(0,AE$10*AC30+AE$11),NA()) -> #DIV/0! | AH30: =IF(AH$10*AF30+AH$11<(ROUNDUP(AG$10/100,0)*100+999),MAX(0,AH$10*AF30+AH$11),NA()) -> #DIV/0! | AV30: =IF(AV$10*AT30+AV$11<(ROUNDUP(AU$10/100,0)*100+999),MAX(0,AV$10*AT30+AV$11),NA()) -> #DIV/0! | AY30: =IF(AY$10*AW30+AY$11<(ROUNDUP(AX$10/100,0)*100+999),MAX(0,AY$10*AW30+AY$11),NA()) -> #DIV/0! | BM30: =IF(BM$10*BK30+BM$11<(ROUNDUP(BL$10/100,0)*100+999),MAX(0,BM$10*BK30+BM$11),NA()) -> #DIV/0! | BP30: =IF(BP$10*BN30+BP$11<(ROUNDUP(BO$10/100,0)*100+999),MAX(0,BP$10*BN30+BP$11),NA()) -> #DIV/0!
AE31: =IF(AE$10*AC31+AE$11<(ROUNDUP(AD$10/100,0)*100+999),MAX(0,AE$10*AC31+AE$11),NA()) -> #DIV/0! | AH31: =IF(AH$10*AF31+AH$11<(ROUNDUP(AG$10/100,0)*100+999),MAX(0,AH$10*AF31+AH$11),NA()) -> #DIV/0! | AV31: =IF(AV$10*AT31+AV$11<(ROUNDUP(AU$10/100,0)*100+999),MAX(0,AV$10*AT31+AV$11),NA()) -> #DIV/0! | AY31: =IF(AY$10*AW31+AY$11<(ROUNDUP(AX$10/100,0)*100+999),MAX(0,AY$10*AW31+AY$11),NA()) -> #DIV/0! | BM31: =IF(BM$10*BK31+BM$11<(ROUNDUP(BL$10/100,0)*100+999),MAX(0,BM$10*BK31+BM$11),NA()) -> #DIV/0! | BP31: =IF(BP$10*BN31+BP$11<(ROUNDUP(BO$10/100,0)*100+999),MAX(0,BP$10*BN31+BP$11),NA()) -> #DIV/0!
AE32: =IF(AE$10*AC32+AE$11<(ROUNDUP(AD$10/100,0)*100+999),MAX(0,AE$10*AC32+AE$11),NA()) -> #DIV/0! | AH32: =IF(AH$10*AF32+AH$11<(ROUNDUP(AG$10/100,0)*100+999),MAX(0,AH$10*AF32+AH$11),NA()) -> #DIV/0! | AV32: =IF(AV$10*AT32+AV$11<(ROUNDUP(AU$10/100,0)*100+999),MAX(0,AV$10*AT32+AV$11),NA()) -> #DIV/0! | AY32: =IF(AY$10*AW32+AY$11<(ROUNDUP(AX$10/100,0)*100+999),MAX(0,AY$10*AW32+AY$11),NA()) -> #DIV/0! | BM32: =IF(BM$10*BK32+BM$11<(ROUNDUP(BL$10/100,0)*100+999),MAX(0,BM$10*BK32+BM$11),NA()) -> #DIV/0! | BP32: =IF(BP$10*BN32+BP$11<(ROUNDUP(BO$10/100,0)*100+999),MAX(0,BP$10*BN32+BP$11),NA()) -> #DIV/0!
AE33: =IF(AE$10*AC33+AE$11<(ROUNDUP(AD$10/100,0)*100+999),MAX(0,AE$10*AC33+AE$11),NA()) -> #DIV/0! | AH33: =IF(AH$10*AF33+AH$11<(ROUNDUP(AG$10/100,0)*100+999),MAX(0,AH$10*AF33+AH$11),NA()) -> #DIV/0! | AV33: =IF(AV$10*AT33+AV$11<(ROUNDUP(AU$10/100,0)*100+999),MAX(0,AV$10*AT33+AV$11),NA()) -> #DIV/0! | AY33: =IF(AY$10*AW33+AY$11<(ROUNDUP(AX$10/100,0)*100+999),MAX(0,AY$10*AW33+AY$11),NA()) -> #DIV/0! | BM33: =IF(BM$10*BK33+BM$11<(ROUNDUP(BL$10/100,0)*100+999),MAX(0,BM$10*BK33+BM$11),NA()) -> #DIV/0! | BP33: =IF(BP$10*BN33+BP$11<(ROUNDUP(BO$10/100,0)*100+999),MAX(0,BP$10*BN33+BP$11),NA()) -> #DIV/0!
AE34: =IF(AE$10*AC34+AE$11<(ROUNDUP(AD$10/100,0)*100+999),MAX(0,AE$10*AC34+AE$11),NA()) -> #DIV/0! | AH34: =IF(AH$10*AF34+AH$11<(ROUNDUP(AG$10/100,0)*100+999),MAX(0,AH$10*AF34+AH$11),NA()) -> #DIV/0! | AV34: =IF(AV$10*AT34+AV$11<(ROUNDUP(AU$10/100,0)*100+999),MAX(0,AV$10*AT34+AV$11),NA()) -> #DIV/0! | AY34: =IF(AY$10*AW34+AY$11<(ROUNDUP(AX$10/100,0)*100+999),MAX(0,AY$10*AW34+AY$11),NA()) -> #DIV/0! | BM34: =IF(BM$10*BK34+BM$11<(ROUNDUP(BL$10/100,0)*100+999),MAX(0,BM$10*BK34+BM$11),NA()) -> #DIV/0! | BP34: =IF(BP$10*BN34+BP$11<(ROUNDUP(BO$10/100,0)*100+999),MAX(0,BP$10*BN34+BP$11),NA()) -> #DIV/0!
AE35: =IF(AE$10*AC35+AE$11<(ROUNDUP(AD$10/100,0)*100+999),MAX(0,AE$10*AC35+AE$11),NA()) -> #DIV/0! | AH35: =IF(AH$10*AF35+AH$11<(ROUNDUP(AG$10/100,0)*100+999),MAX(0,AH$10*AF35+AH$11),NA()) -> #DIV/0! | AV35: =IF(AV$10*AT35+AV$11<(ROUNDUP(AU$10/100,0)*100+999),MAX(0,AV$10*AT35+AV$11),NA()) -> #DIV/0! | AY35: =IF(AY$10*AW35+AY$11<(ROUNDUP(AX$10/100,0)*100+999),MAX(0,AY$10*AW35+AY$11),NA()) -> #DIV/0! | BM35: =IF(BM$10*BK35+BM$11<(ROUNDUP(BL$10/100,0)*100+999),MAX(0,BM$10*BK35+BM$11),NA()) -> #DIV/0! | BP35: =IF(BP$10*BN35+BP$11<(ROUNDUP(BO$10/100,0)*100+999),MAX(0,BP$10*BN35+BP$11),NA()) -> #DIV/0!
AE36: =IF(AE$10*AC36+AE$11<(ROUNDUP(AD$10/100,0)*100+999),MAX(0,AE$10*AC36+AE$11),NA()) -> #DIV/0! | AH36: =IF(AH$10*AF36+AH$11<(ROUNDUP(AG$10/100,0)*100+999),MAX(0,AH$10*AF36+AH$11),NA()) -> #DIV/0! | AV36: =IF(AV$10*AT36+AV$11<(ROUNDUP(AU$10/100,0)*100+999),MAX(0,AV$10*AT36+AV$11),NA()) -> #DIV/0! | AY36: =IF(AY$10*AW36+AY$11<(ROUNDUP(AX$10/100,0)*100+999),MAX(0,AY$10*AW36+AY$11),NA()) -> #DIV/0! | BM36: =IF(BM$10*BK36+BM$11<(ROUNDUP(BL$10/100,0)*100+999),MAX(0,BM$10*BK36+BM$11),NA()) -> #DIV/0! | BP36: =IF(BP$10*BN36+BP$11<(ROUNDUP(BO$10/100,0)*100+999),MAX(0,BP$10*BN36+BP$11),NA()) -> #DIV/0!
AE37: =IF(AE$10*AC37+AE$11<(ROUNDUP(AD$10/100,0)*100+999),MAX(0,AE$10*AC37+AE$11),NA()) -> #DIV/0! | AH37: =IF(AH$10*AF37+AH$11<(ROUNDUP(AG$10/100,0)*100+999),MAX(0,AH$10*AF37+AH$11),NA()) -> #DIV/0! | AV37: =IF(AV$10*AT37+AV$11<(ROUNDUP(AU$10/100,0)*100+999),MAX(0,AV$10*AT37+AV$11),NA()) -> #DIV/0! | AY37: =IF(AY$10*AW37+AY$11<(ROUNDUP(AX$10/100,0)*100+999),MAX(0,AY$10*AW37+AY$11),NA()) -> #DIV/0! | BM37: =IF(BM$10*BK37+BM$11<(ROUNDUP(BL$10/100,0)*100+999),MAX(0,BM$10*BK37+BM$11),NA()) -> #DIV/0! | BP37: =IF(BP$10*BN37+BP$11<(ROUNDUP(BO$10/100,0)*100+999),MAX(0,BP$10*BN37+BP$11),NA()) -> #DIV/0!
AE38: =IF(AE$10*AC38+AE$11<(ROUNDUP(AD$10/100,0)*100+999),MAX(0,AE$10*AC38+AE$11),NA()) -> #DIV/0! | AH38: =IF(AH$10*AF38+AH$11<(ROUNDUP(AG$10/100,0)*100+999),MAX(0,AH$10*AF38+AH$11),NA()) -> #DIV/0! | AV38: =IF(AV$10*AT38+AV$11<(ROUNDUP(AU$10/100,0)*100+999),MAX(0,AV$10*AT38+AV$11),NA()) -> #DIV/0! | AY38: =IF(AY$10*AW38+AY$11<(ROUNDUP(AX$10/100,0)*100+999),MAX(0,AY$10*AW38+AY$11),NA()) -> #DIV/0! | BM38: =IF(BM$10*BK38+BM$11<(ROUNDUP(BL$10/100,0)*100+999),MAX(0,BM$10*BK38+BM$11),NA()) -> #DIV/0! | BP38: =IF(BP$10*BN38+BP$11<(ROUNDUP(BO$10/100,0)*100+999),MAX(0,BP$10*BN38+BP$11),NA()) -> #DIV/0!
AE39: =IF(AE$10*AC39+AE$11<(ROUNDUP(AD$10/100,0)*100+999),MAX(0,AE$10*AC39+AE$11),NA()) -> #DIV/0! | AH39: =IF(AH$10*AF39+AH$11<(ROUNDUP(AG$10/100,0)*100+999),MAX(0,AH$10*AF39+AH$11),NA()) -> #DIV/0! | AV39: =IF(AV$10*AT39+AV$11<(ROUNDUP(AU$10/100,0)*100+999),MAX(0,AV$10*AT39+AV$11),NA()) -> #DIV/0! | AY39: =IF(AY$10*AW39+AY$11<(ROUNDUP(AX$10/100,0)*100+999),MAX(0,AY$10*AW39+AY$11),NA()) -> #DIV/0! | BM39: =IF(BM$10*BK39+BM$11<(ROUNDUP(BL$10/100,0)*100+999),MAX(0,BM$10*BK39+BM$11),NA()) -> #DIV/0! | BP39: =IF(BP$10*BN39+BP$11<(ROUNDUP(BO$10/100,0)*100+999),MAX(0,BP$10*BN39+BP$11),NA()) -> #DIV/0!
B40: If additional images are necessary, they may be placed below each section. | S40: If additional images are necessary, they may be placed below each section. | AE40: =IF(AE$10*AC40+AE$11<(ROUNDUP(AD$10/100,0)*100+999),MAX(0,AE$10*AC40+AE$11),NA()) -> #DIV/0! | AH40: =IF(AH$10*AF40+AH$11<(ROUNDUP(AG$10/100,0)*100+999),MAX(0,AH$10*AF40+AH$11),NA()) -> #DIV/0! | AJ40: If additional images are necessary, they may be placed below each section. | AV40: =IF(AV$10*AT40+AV$11<(ROUNDUP(AU$10/100,0)*100+999),MAX(0,AV$10*AT40+AV$11),NA()) -> #DIV/0! | AY40: =IF(AY$10*AW40+AY$11<(ROUNDUP(AX$10/100,0)*100+999),MAX(0,AY$10*AW40+AY$11),NA()) -> #DIV/0! | BA40: If additional images are necessary, they may be placed below each section. | BM40: =IF(BM$10*BK40+BM$11<(ROUNDUP(BL$10/100,0)*100+999),MAX(0,BM$10*BK40+BM$11),NA()) -> #DIV/0! | BP40: =IF(BP$10*BN40+BP$11<(ROUNDUP(BO$10/100,0)*100+999),MAX(0,BP$10*BN40+BP$11),NA()) -> #DIV/0!
AE41: =IF(AE$10*AC41+AE$11<(ROUNDUP(AD$10/100,0)*100+999),MAX(0,AE$10*AC41+AE$11),NA()) -> #DIV/0! | AH41: =IF(AH$10*AF41+AH$11<(ROUNDUP(AG$10/100,0)*100+999),MAX(0,AH$10*AF41+AH$11),NA()) -> #DIV/0! | AV41: =IF(AV$10*AT41+AV$11<(ROUNDUP(AU$10/100,0)*100+999),MAX(0,AV$10*AT41+AV$11),NA()) -> #DIV/0! | AY41: =IF(AY$10*AW41+AY$11<(ROUNDUP(AX$10/100,0)*100+999),MAX(0,AY$10*AW41+AY$11),NA()) -> #DIV/0! | BM41: =IF(BM$10*BK41+BM$11<(ROUNDUP(BL$10/100,0)*100+999),MAX(0,BM$10*BK41+BM$11),NA()) -> #DIV/0! | BP41: =IF(BP$10*BN41+BP$11<(ROUNDUP(BO$10/100,0)*100+999),MAX(0,BP$10*BN41+BP$11),NA()) -> #DIV/0!
...

Sheet F.10.5 Battery Attachment
A1: MATERIAL LIST IS LINKED TO THE MODULES AND CONTAINER TAB. | E1: =IF($A$25="mm","Note: Forces are given in Pa, not Mpa or Gpa.","Note: Forces are given in psi, not ksi.") -> Note: Forces are given in Pa, not Mpa or Gpa.
E2: Material | G2: =IF($A$25="mm","E (Pa)","E (psi)") -> E (Pa) | I2: =IF($A$25="mm","S_Ultimate (Pa)","S_Ultimate (psi)") -> S_Ultimate (Pa) | K2: =IF($A$25="mm","Shear (Pa)","Shear (psi)") -> Shear (Pa) | L2: =_xlfn.CONCAT("S_Yield ",IF($A$25="mm","(Pa)","(psi)")) -> S_Yield (Pa) | M2: FEA is not accepted anywhere
E3: Steel Unwelded | G3: =IF($A$25="mm",200*10^9,29*10^6) -> 200000000000 | I3: =IF($A$25="mm",365*10^6,52.9*10^3) -> 365000000 | K3: =I3*0.577 -> 2.10605e+08 | L3: =IF($A$25="mm",305*10^6,44.2*10^3) -> 305000000 | M3: in the SES or Tech Inspection.
E4: Steel Welded | G4: =IF($A$25="mm",200*10^9,29*10^6) -> 200000000000 | I4: =IF($A$25="mm",300*10^6,43.5*10^3) -> 300000000 | K4: =I4*0.577 -> 173100000 | L4: =(L3/I3)*I4 -> 2.5068493e+08 | Q4: SEE GUIDANCE IMAGES TO THE RIGHT IN COLUMN DR
E5: 6061-T6 Unwelded | G5: =IF($A$25="mm",69*10^9,10*10^6) -> 69000000000 | I5: =IF($A$25="mm",290*10^6,42.1*10^3) -> 290000000 | K5: =I5*0.577 -> 167330000 | L5: =IF($A$25="mm",240*10^6,34.8*10^3) -> 240000000
E6: 6061-T6 Welded | G6: =IF($A$25="mm",69*10^9,10*10^6) -> 69000000000 | I6: =IF($A$25="mm",175*10^6,25.4*10^3) -> 175000000 | K6: =I6*0.577 -> 1.00975e+08 | L6: =IF($A$25="mm",105*10^6,25.4*10^3) -> 105000000
E7: 5052-H32 Unwelded | G7: =IF($A$25="mm",70.3*10^9,10.2*10^6) -> 70300000000 | I7: =IF($A$25="mm",215*10^6,31.2*10^3) -> 215000000 | K7: =I7*0.577 -> 1.24055e+08 | L7: =IF($A$25="mm",160*10^6,23.2*10^3) -> 160000000
E8: 5052-H32 Welded | G8: =IF($A$25="mm",70.3*10^9,10.2*10^6) -> 70300000000 | I8: =IF($A$25="mm",170*10^6,24.6*10^3) -> 170000000 | K8: =I8*0.577 -> 98090000 | L8: =IF($A$25="mm",65*10^6,9.4*10^3) -> 65000000
A9: Doubled skin must repeat whole layup. Scroll up if Layup Used blank. | E9: ='F.10.1-4 Modules And Container'!E9 -> Other Unwelded | G9: ='F.10.1-4 Modules And Container'!G9 -> 0 | I9: ='F.10.1-4 Modules And Container'!I9 -> 0 | K9: ='F.10.1-4 Modules And Container'!K9 -> 0 | L9: ='F.10.1-4 Modules And Container'!L9 -> 0 | M9: Core | N9: Outer | O9: Inner | Q9: Show tractive battery / frame with all mounts. | AE9: Include fastener data sheets.
E10: ='F.10.1-4 Modules And Container'!E10 -> Other Welded | G10: ='F.10.1-4 Modules And Container'!G10 -> 0 | I10: ='F.10.1-4 Modules And Container'!I10 -> 0 | K10: ='F.10.1-4 Modules And Container'!K10 -> 0 | L10: ='F.10.1-4 Modules And Container'!L10 -> 0 | M10: =IF($A$25="mm","mm","in") -> mm | N10: =IF($A$25="mm","mm","in") -> mm | O10: =IF($A$25="mm","mm","in") -> mm
D11: {=IF($E11="","",INDIRECT("'"&$E11&"'!$A$27"))} -> #REF! | E11: =IF('F.10.1-4 Modules And Container'!E11="","",'F.10.1-4 Modules And Container'!E11) -> RENAME F.4.2 Composite | G11: {=IF($E11="","", IF($A$25="mm",INDIRECT("'"&$E11&"'!$AK$82"),INDIRECT("'"&$E11&"'!$AK$83")))} -> #REF! | I11: {=IF($E11="","", IF($A$25="mm",INDIRECT("'"&$E11&"'!$AK$85"),INDIRECT("'"&$E11&"'!$AK$86")))} -> #REF! | K11: {=IF($E11="","", IF($A$25="mm",INDIRECT("'"&$E11&"'!$AY$62"),INDIRECT("'"&$E11&"'!$AY$63")))} -> #REF! | M11: {=IF($E11="","", ROUND(IF($A$25="mm",1,1/25.4)*INDIRECT("'"&$E11&"'!$AK$61"),3))} -> #REF! | N11: {=IF($E11="","", ROUND(IF($A$25="mm",1,1/25.4)*INDIRECT("'"&$E11&"'!$AK$62"),3))} -> #REF! | O11: {=IF($E11="","", ROUND(IF($A$25="mm",1,1/25.4)*INDIRECT("'"&$E11&"'!$AK$63"),3))} -> #REF! | Q11: Identify mounts by corresponding number / corner name.
D12: {=IF($E12="","",INDIRECT("'"&$E12&"'!$A$27"))} | E12: =IF('F.10.1-4 Modules And Container'!E12="","",'F.10.1-4 Modules And Container'!E12) | G12: {=IF($E12="","", IF($A$25="mm",INDIRECT("'"&$E12&"'!$AK$82"),INDIRECT("'"&$E12&"'!$AK$83")))} | I12: {=IF($E12="","", IF($A$25="mm",INDIRECT("'"&$E12&"'!$AK$85"),INDIRECT("'"&$E12&"'!$AK$86")))} | K12: {=IF($E12="","", IF($A$25="mm",INDIRECT("'"&$E12&"'!$AY$62"),INDIRECT("'"&$E12&"'!$AY$63")))} | M12: {=IF($E12="","", ROUND(IF($A$25="mm",1,1/25.4)*INDIRECT("'"&$E12&"'!$AK$61"),3))} | N12: {=IF($E12="","", ROUND(IF($A$25="mm",1,1/25.4)*INDIRECT("'"&$E12&"'!$AK$62"),3))} | O12: {=IF($E12="","", ROUND(IF($A$25="mm",1,1/25.4)*INDIRECT("'"&$E12&"'!$AK$63"),3))}
D13: {=IF($E13="","",INDIRECT("'"&$E13&"'!$A$27"))} | E13: =IF('F.10.1-4 Modules And Container'!E13="","",'F.10.1-4 Modules And Container'!E13) | G13: {=IF($E13="","", IF($A$25="mm",INDIRECT("'"&$E13&"'!$AK$82"),INDIRECT("'"&$E13&"'!$AK$83")))} | I13: {=IF($E13="","", IF($A$25="mm",INDIRECT("'"&$E13&"'!$AK$85"),INDIRECT("'"&$E13&"'!$AK$86")))} | K13: {=IF($E13="","", IF($A$25="mm",INDIRECT("'"&$E13&"'!$AY$62"),INDIRECT("'"&$E13&"'!$AY$63")))} | M13: {=IF($E13="","", ROUND(IF($A$25="mm",1,1/25.4)*INDIRECT("'"&$E13&"'!$AK$61"),3))} | N13: {=IF($E13="","", ROUND(IF($A$25="mm",1,1/25.4)*INDIRECT("'"&$E13&"'!$AK$62"),3))} | O13: {=IF($E13="","", ROUND(IF($A$25="mm",1,1/25.4)*INDIRECT("'"&$E13&"'!$AK$63"),3))} | Q13: Show mounts relative to module structures.
D14: {=IF($E14="","",INDIRECT("'"&$E14&"'!$A$27"))} | E14: =IF('F.10.1-4 Modules And Container'!E14="","",'F.10.1-4 Modules And Container'!E14) | G14: {=IF($E14="","", IF($A$25="mm",INDIRECT("'"&$E14&"'!$AK$82"),INDIRECT("'"&$E14&"'!$AK$83")))} | I14: {=IF($E14="","", IF($A$25="mm",INDIRECT("'"&$E14&"'!$AK$85"),INDIRECT("'"&$E14&"'!$AK$86")))} | K14: {=IF($E14="","", IF($A$25="mm",INDIRECT("'"&$E14&"'!$AY$62"),INDIRECT("'"&$E14&"'!$AY$63")))} | M14: {=IF($E14="","", ROUND(IF($A$25="mm",1,1/25.4)*INDIRECT("'"&$E14&"'!$AK$61"),3))} | N14: {=IF($E14="","", ROUND(IF($A$25="mm",1,1/25.4)*INDIRECT("'"&$E14&"'!$AK$62"),3))} | O14: {=IF($E14="","", ROUND(IF($A$25="mm",1,1/25.4)*INDIRECT("'"&$E14&"'!$AK$63"),3))}
D15: {=IF($E15="","",INDIRECT("'"&$E15&"'!$A$27"))} | E15: =IF('F.10.1-4 Modules And Container'!E15="","",'F.10.1-4 Modules And Container'!E15) | G15: {=IF($E15="","", IF($A$25="mm",INDIRECT("'"&$E15&"'!$AK$82"),INDIRECT("'"&$E15&"'!$AK$83")))} | I15: {=IF($E15="","", IF($A$25="mm",INDIRECT("'"&$E15&"'!$AK$85"),INDIRECT("'"&$E15&"'!$AK$86")))} | K15: {=IF($E15="","", IF($A$25="mm",INDIRECT("'"&$E15&"'!$AY$62"),INDIRECT("'"&$E15&"'!$AY$63")))} | M15: {=IF($E15="","", ROUND(IF($A$25="mm",1,1/25.4)*INDIRECT("'"&$E15&"'!$AK$61"),3))} | N15: {=IF($E15="","", ROUND(IF($A$25="mm",1,1/25.4)*INDIRECT("'"&$E15&"'!$AK$62"),3))} | O15: {=IF($E15="","", ROUND(IF($A$25="mm",1,1/25.4)*INDIRECT("'"&$E15&"'!$AK$63"),3))}
A16: {=IF(ISREF(INDIRECT("'F.3.4-5 Tube Chassis"&"'!G8")),INDIRECT("'F.3.4-5 Tube Chassis"&"'!G8"),INDIRECT("'F.3.4 Steel Tube"&"'!G8"))} -> Select Drop Down | D16: {=IF($E16="","",INDIRECT("'"&$E16&"'!$A$27"))} | E16: =IF('F.10.1-4 Modules And Container'!E16="","",'F.10.1-4 Modules And Container'!E16) | G16: {=IF($E16="","", IF($A$25="mm",INDIRECT("'"&$E16&"'!$AK$82"),INDIRECT("'"&$E16&"'!$AK$83")))} | I16: {=IF($E16="","", IF($A$25="mm",INDIRECT("'"&$E16&"'!$AK$85"),INDIRECT("'"&$E16&"'!$AK$86")))} | K16: {=IF($E16="","", IF($A$25="mm",INDIRECT("'"&$E16&"'!$AY$62"),INDIRECT("'"&$E16&"'!$AY$63")))} | M16: {=IF($E16="","", ROUND(IF($A$25="mm",1,1/25.4)*INDIRECT("'"&$E16&"'!$AK$61"),3))} | N16: {=IF($E16="","", ROUND(IF($A$25="mm",1,1/25.4)*INDIRECT("'"&$E16&"'!$AK$62"),3))} | O16: {=IF($E16="","", ROUND(IF($A$25="mm",1,1/25.4)*INDIRECT("'"&$E16&"'!$AK$63"),3))}
A17: =IF(A16="IC - Internal Combustion","N/A", IF(OR(K63="BLANK",K69="BLANK",COUNTIF(A56:DH57,"BLANK")),"BLANK", IF(COUNTIF(A56:DH57,"REJECT"),"REJECT", IF(COUNTIF(A56:DH57,"CHECK"),"CHECK","EQ")))) -> BLANK | D17: {=IF($E17="","",INDIRECT("'"&$E17&"'!$A$27"))} | E17: =IF('F.10.1-4 Modules And Container'!E17="","",'F.10.1-4 Modules And Container'!E17) | G17: {=IF($E17="","", IF($A$25="mm",INDIRECT("'"&$E17&"'!$AK$82"),INDIRECT("'"&$E17&"'!$AK$83")))} | I17: {=IF($E17="","", IF($A$25="mm",INDIRECT("'"&$E17&"'!$AK$85"),INDIRECT("'"&$E17&"'!$AK$86")))} | K17: {=IF($E17="","", IF($A$25="mm",INDIRECT("'"&$E17&"'!$AY$62"),INDIRECT("'"&$E17&"'!$AY$63")))} | M17: {=IF($E17="","", ROUND(IF($A$25="mm",1,1/25.4)*INDIRECT("'"&$E17&"'!$AK$61"),3))} | N17: {=IF($E17="","", ROUND(IF($A$25="mm",1,1/25.4)*INDIRECT("'"&$E17&"'!$AK$62"),3))} | O17: {=IF($E17="","", ROUND(IF($A$25="mm",1,1/25.4)*INDIRECT("'"&$E17&"'!$AK$63"),3))}
D18: {=IF($E18="","",INDIRECT("'"&$E18&"'!$A$27"))} | E18: =IF('F.10.1-4 Modules And Container'!E18="","",'F.10.1-4 Modules And Container'!E18) | G18: {=IF($E18="","", IF($A$25="mm",INDIRECT("'"&$E18&"'!$AK$82"),INDIRECT("'"&$E18&"'!$AK$83")))} | I18: {=IF($E18="","", IF($A$25="mm",INDIRECT("'"&$E18&"'!$AK$85"),INDIRECT("'"&$E18&"'!$AK$86")))} | K18: {=IF($E18="","", IF($A$25="mm",INDIRECT("'"&$E18&"'!$AY$62"),INDIRECT("'"&$E18&"'!$AY$63")))} | M18: {=IF($E18="","", ROUND(IF($A$25="mm",1,1/25.4)*INDIRECT("'"&$E18&"'!$AK$61"),3))} | N18: {=IF($E18="","", ROUND(IF($A$25="mm",1,1/25.4)*INDIRECT("'"&$E18&"'!$AK$62"),3))} | O18: {=IF($E18="","", ROUND(IF($A$25="mm",1,1/25.4)*INDIRECT("'"&$E18&"'!$AK$63"),3))}
D19: {=IF($E19="","",INDIRECT("'"&$E19&"'!$A$27"))} | E19: =IF('F.10.1-4 Modules And Container'!E19="","",'F.10.1-4 Modules And Container'!E19) | G19: {=IF($E19="","", IF($A$25="mm",INDIRECT("'"&$E19&"'!$AK$82"),INDIRECT("'"&$E19&"'!$AK$83")))} | I19: {=IF($E19="","", IF($A$25="mm",INDIRECT("'"&$E19&"'!$AK$85"),INDIRECT("'"&$E19&"'!$AK$86")))} | K19: {=IF($E19="","", IF($A$25="mm",INDIRECT("'"&$E19&"'!$AY$62"),INDIRECT("'"&$E19&"'!$AY$63")))} | M19: {=IF($E19="","", ROUND(IF($A$25="mm",1,1/25.4)*INDIRECT("'"&$E19&"'!$AK$61"),3))} | N19: {=IF($E19="","", ROUND(IF($A$25="mm",1,1/25.4)*INDIRECT("'"&$E19&"'!$AK$62"),3))} | O19: {=IF($E19="","", ROUND(IF($A$25="mm",1,1/25.4)*INDIRECT("'"&$E19&"'!$AK$63"),3))}
D20: {=IF($E20="","",INDIRECT("'"&$E20&"'!$A$27"))} | E20: =IF('F.10.1-4 Modules And Container'!E20="","",'F.10.1-4 Modules And Container'!E20) | G20: {=IF($E20="","", IF($A$25="mm",INDIRECT("'"&$E20&"'!$AK$82"),INDIRECT("'"&$E20&"'!$AK$83")))} | I20: {=IF($E20="","", IF($A$25="mm",INDIRECT("'"&$E20&"'!$AK$85"),INDIRECT("'"&$E20&"'!$AK$86")))} | K20: {=IF($E20="","", IF($A$25="mm",INDIRECT("'"&$E20&"'!$AY$62"),INDIRECT("'"&$E20&"'!$AY$63")))} | M20: {=IF($E20="","", ROUND(IF($A$25="mm",1,1/25.4)*INDIRECT("'"&$E20&"'!$AK$61"),3))} | N20: {=IF($E20="","", ROUND(IF($A$25="mm",1,1/25.4)*INDIRECT("'"&$E20&"'!$AK$62"),3))} | O20: {=IF($E20="","", ROUND(IF($A$25="mm",1,1/25.4)*INDIRECT("'"&$E20&"'!$AK$63"),3))}
D21: {=IF($E21="","",INDIRECT("'"&$E21&"'!$A$27"))} | E21: =IF('F.10.1-4 Modules And Container'!E21="","",'F.10.1-4 Modules And Container'!E21) | G21: {=IF($E21="","", IF($A$25="mm",INDIRECT("'"&$E21&"'!$AK$82"),INDIRECT("'"&$E21&"'!$AK$83")))} | I21: {=IF($E21="","", IF($A$25="mm",INDIRECT("'"&$E21&"'!$AK$85"),INDIRECT("'"&$E21&"'!$AK$86")))} | K21: {=IF($E21="","", IF($A$25="mm",INDIRECT("'"&$E21&"'!$AY$62"),INDIRECT("'"&$E21&"'!$AY$63")))} | M21: {=IF($E21="","", ROUND(IF($A$25="mm",1,1/25.4)*INDIRECT("'"&$E21&"'!$AK$61"),3))} | N21: {=IF($E21="","", ROUND(IF($A$25="mm",1,1/25.4)*INDIRECT("'"&$E21&"'!$AK$62"),3))} | O21: {=IF($E21="","", ROUND(IF($A$25="mm",1,1/25.4)*INDIRECT("'"&$E21&"'!$AK$63"),3))}
A25: {=IF(ISREF(INDIRECT("'F.3.4-5 Tube Chassis"&"'!$A$25")),INDIRECT("'F.3.4-5 Tube Chassis"&"'!$A$25"),INDIRECT("'F.3.4 Steel Tube"&"'!$A$25"))} -> mm
U32: SEE GUIDANCE IMAGES IN COLUMN DR
E39: Total X/Y/Z dimensions of Battery assembly. | O39: 25mm gap to side, rear, driver. | U39: =IF($N$70="Mass Based","Tractive Battery Mount 1", IF($N$72="Front/Rear","Top Left Tractive Battery Mount", IF($N$72="Top/Bottom","Front Left Tractive Battery Mount", "Top Front Tractive Battery Mount"))) -> Top Front Tractive Battery Mount | AE39: =IF($N$70="Mass Based","Tractive Battery Mount 2", IF($N$72="Front/Rear","Top Right Tractive Battery Mount", IF($N$72="Top/Bottom","Front Right Tractive Battery Mount", "Top Rear Tractive Battery Mount"))) -> Top Rear Tractive Battery Mount | AO39: =IF($N$70="Mass Based","Tractive Battery Mount 3", IF($N$72="Front/Rear","Bottom Left Tractive Battery Mount", IF($N$72="Top/Bottom","Rear Left Tractive Battery Mount", "Bottom Front Tractive Battery Mount"))) -> Bottom Front Tractive Battery Mount | AY39: =IF($N$70="Mass Based","Tractive Battery Mount 4", IF($N$72="Front/Rear","Bottom Right Tractive Battery Mount", IF($N$72="Top/Bottom","Rear Right Tractive Battery Mount", "Bottom Rear Tractive Battery Mount"))) -> Bottom Rear Tractive Battery Mount | BI39: Tractive Battery Mount 5 | BS39: =IF($N$70="Mass Based","Chassis Mount 1", IF($N$73="Front/Rear","Top Left Chassis Mount", IF($N$73="Top/Bottom","Front Left Chassis Mount", "Top Front Chassis Mount"))) -> Top Front Chassis Mount | CC39: =IF($N$70="Mass Based","Chassis Mount 2", IF($N$73="Front/Rear","Top Right Chassis Mount", IF($N$73="Top/Bottom","Front Right Chassis Mount", "Top Rear Chassis Mount"))) -> Top Rear Chassis Mount | CM39: =IF($N$70="Mass Based","Chassis Mount 3", IF($N$73="Front/Rear","Bottom Left Chassis Mount", IF($N$73="Top/Bottom","Rear Left Chassis Mount", "Bottom Front Chassis Mount"))) -> Bottom Front Chassis Mount | CW39: =IF($N$70="Mass Based","Chassis Mount 4", IF($N$73="Front/Rear","Bottom Right Chassis Mount", IF($N$73="Top/Bottom","Rear Right Chassis Mount", "Bottom Rear Chassis Mount"))) -> Bottom Rear Chassis Mount | DG39: Chassis Mount 5
E41: For Overnight Storage container.
U53: Show all dimensions entered below. | AE53: Show all dimensions entered below. | AO53: Show all dimensions entered below. | AY53: Show all dimensions entered below. | BI53: Show all dimensions entered below. | BS53: Show all dimensions entered below. | CC53: Show all dimensions entered below. | CM53: Show all dimensions entered below. | CW53: Show all dimensions entered below. | DG53: Show all dimensions entered below.
